{
 "cells": [
  {
   "cell_type": "code",
   "execution_count": 1,
   "id": "f57ca59e",
   "metadata": {},
   "outputs": [],
   "source": [
    "import numpy as np\n",
    "import pandas as pd\n",
    "import os\n",
    "from autogluon.tabular import TabularDataset, TabularPredictor"
   ]
  },
  {
   "cell_type": "code",
   "execution_count": 2,
   "id": "796a08d1",
   "metadata": {},
   "outputs": [],
   "source": [
    "# performance evaluation\n",
    "def macro_f1(target,fit):\n",
    "\n",
    "    \"\"\"\n",
    "    计算得分\n",
    "    :param target_df: [sn,fault_time,label]\n",
    "    :param submit_df: [sn,fault_time,label]\n",
    "    :return:\n",
    "    \"\"\"\n",
    "\n",
    "    weights =  [3  /  7,  2  /  7,  1  /  7,  1  /  7]\n",
    "    \n",
    "    macro_F1 =  0.\n",
    "    for i in  range(len(weights)):\n",
    "        TP =  sum((target == i) & (fit == i))\n",
    "        FP =  sum((target != i) & (fit == i))\n",
    "        FN =  sum((target == i) & (fit != i))\n",
    "        precision = TP /  (TP + FP)  if  (TP + FP)  >  0  else  0\n",
    "        recall = TP /  (TP + FN)  if  (TP + FN)  >  0  else  0\n",
    "        F1 =  2  * precision * recall /  (precision + recall)  if  (precision + recall)  >  0  else  0\n",
    "        macro_F1 += weights[i]  * F1\n",
    "        \n",
    "        # print('Task %d:\\n Prcesion %.2f, Recall %.2f, F1 %.2f' % (i+1, precision, recall, F1))\n",
    "        \n",
    "    return macro_F1"
   ]
  },
  {
   "cell_type": "code",
   "execution_count": 3,
   "id": "1fb69fc7",
   "metadata": {},
   "outputs": [],
   "source": [
    "train_data = TabularDataset('C:\\\\Users\\\\whchi\\\\Downloads\\\\Log-diagnosis-main\\\\Log-diagnosis-main\\\\pre_contest\\\\dataset\\\\train.csv')\n"
   ]
  },
  {
   "cell_type": "code",
   "execution_count": 4,
   "id": "137ce538",
   "metadata": {},
   "outputs": [],
   "source": [
    "from autogluon.core.metrics import make_scorer\n",
    "ag_macro_f1_scorer = make_scorer(name='macro_f1',\n",
    "                                 score_func=macro_f1,\n",
    "                                 optimum=1,\n",
    "                                 greater_is_better=True)\n"
   ]
  },
  {
   "cell_type": "code",
   "execution_count": 8,
   "id": "a3ffe78f",
   "metadata": {},
   "outputs": [
    {
     "name": "stderr",
     "output_type": "stream",
     "text": [
      "No path specified. Models will be saved in: \"AutogluonModels/ag-20220326_112328\\\"\n",
      "Presets specified: ['best_quality']\n",
      "Beginning AutoGluon training ...\n",
      "AutoGluon will save models to \"AutogluonModels/ag-20220326_112328\\\"\n",
      "AutoGluon Version:  0.4.0\n",
      "Python Version:     3.9.0\n",
      "Operating System:   Windows\n",
      "Train Data Rows:    13307\n",
      "Train Data Columns: 1\n",
      "Label Column: label\n",
      "Preprocessing data ...\n",
      "AutoGluon infers your prediction problem is: 'multiclass' (because dtype of label-column == int, but few unique label-values observed).\n",
      "\t4 unique label values:  [1, 2, 3, 0]\n",
      "\tIf 'multiclass' is not the correct problem_type, please manually specify the problem_type parameter during predictor init (You may specify problem_type as one of: ['binary', 'multiclass', 'regression'])\n",
      "Train Data Class Count: 4\n",
      "Using Feature Generators to preprocess the data ...\n",
      "Fitting AutoMLPipelineFeatureGenerator...\n",
      "\tAvailable Memory:                    17087.68 MB\n",
      "\tTrain Data (Original)  Memory Usage: 3.65 MB (0.0% of available memory)\n",
      "\tInferring data type of each feature based on column values. Set feature_metadata_in to manually specify special dtypes of the features.\n",
      "\tStage 1 Generators:\n",
      "\t\tFitting AsTypeFeatureGenerator...\n",
      "\tStage 2 Generators:\n",
      "\t\tFitting FillNaFeatureGenerator...\n",
      "\tStage 3 Generators:\n",
      "\t\tFitting CategoryFeatureGenerator...\n",
      "\t\t\tFitting CategoryMemoryMinimizeFeatureGenerator...\n",
      "\t\tFitting TextSpecialFeatureGenerator...\n",
      "\t\t\tFitting BinnedFeatureGenerator...\n",
      "\t\t\tFitting DropDuplicatesFeatureGenerator...\n",
      "\t\tFitting TextNgramFeatureGenerator...\n",
      "\t\t\tFitting CountVectorizer for text features: ['msg']\n",
      "\t\t\tCountVectorizer fit with vocabulary size = 1483\n",
      "\tStage 4 Generators:\n",
      "\t\tFitting DropUniqueFeatureGenerator...\n",
      "\tTypes of features in original data (raw dtype, special dtypes):\n",
      "\t\t('object', ['text']) : 1 | ['msg']\n",
      "\tTypes of features in processed data (raw dtype, special dtypes):\n",
      "\t\t('category', ['text_as_category'])  :    1 | ['msg']\n",
      "\t\t('int', ['binned', 'text_special']) :   18 | ['msg.char_count', 'msg.word_count', 'msg.capital_ratio', 'msg.lower_ratio', 'msg.digit_ratio', ...]\n",
      "\t\t('int', ['text_ngram'])             : 1484 | ['__nlp__.000000', '__nlp__.000000 0203c0a80101', '__nlp__.001c4c', '__nlp__.0203c0a80101', '__nlp__.0x10', ...]\n",
      "\t4.5s = Fit runtime\n",
      "\t1 features in original data used to generate 1503 features in processed data.\n",
      "\tTrain Data (Processed) Memory Usage: 39.76 MB (0.2% of available memory)\n",
      "Data preprocessing and feature engineering runtime = 4.66s ...\n",
      "AutoGluon will gauge predictive performance using evaluation metric: 'macro_f1'\n",
      "\tTo change this, specify the eval_metric parameter of Predictor()\n",
      "AutoGluon will fit 2 stack levels (L1 to L2) ...\n",
      "Fitting 13 L1 models ...\n",
      "Fitting model: KNeighborsUnif_BAG_L1 ...\n",
      "\t0.5695\t = Validation score   (macro_f1)\n",
      "\t0.29s\t = Training   runtime\n",
      "\t7.15s\t = Validation runtime\n",
      "Fitting model: KNeighborsDist_BAG_L1 ...\n",
      "\t0.5736\t = Validation score   (macro_f1)\n",
      "\t0.29s\t = Training   runtime\n",
      "\t7.18s\t = Validation runtime\n",
      "Fitting model: NeuralNetFastAI_BAG_L1 ...\n",
      "\tFitting 8 child models (S1F1 - S1F8) | Fitting with ParallelLocalFoldFittingStrategy\n",
      "\tWarning: Exception caused NeuralNetFastAI_BAG_L1 to fail during training... Skipping this model.\n",
      "\t\t\u001b[36mray::_ray_fit()\u001b[39m (pid=30736, ip=192.168.1.5)\n",
      "  File \"python\\ray\\_raylet.pyx\", line 568, in ray._raylet.execute_task\n",
      "  File \"python\\ray\\_raylet.pyx\", line 572, in ray._raylet.execute_task\n",
      "  File \"D:\\Anaconda3\\envs\\py39\\lib\\site-packages\\autogluon\\core\\models\\ensemble\\fold_fitting_strategy.py\", line 288, in _ray_fit\n",
      "    fold_model.fit(X=X_fold, y=y_fold, X_val=X_val_fold, y_val=y_val_fold,\n",
      "  File \"D:\\Anaconda3\\envs\\py39\\lib\\site-packages\\autogluon\\core\\models\\abstract\\abstract_model.py\", line 577, in fit\n",
      "    out = self._fit(**kwargs)\n",
      "  File \"D:\\Anaconda3\\envs\\py39\\lib\\site-packages\\autogluon\\tabular\\models\\fastainn\\tabular_nn_fastai.py\", line 169, in _fit\n",
      "    try_import_fastai()\n",
      "  File \"D:\\Anaconda3\\envs\\py39\\lib\\site-packages\\autogluon\\core\\utils\\try_import.py\", line 128, in try_import_fastai\n",
      "    import autogluon.tabular.models.fastainn.imports_helper\n",
      "  File \"D:\\Anaconda3\\envs\\py39\\lib\\site-packages\\autogluon\\tabular\\models\\fastainn\\imports_helper.py\", line 1, in <module>\n",
      "    from fastai.tabular.all import *\n",
      "  File \"D:\\Anaconda3\\envs\\py39\\lib\\site-packages\\fastai\\tabular\\all.py\", line 1, in <module>\n",
      "    from ..basics import *\n",
      "  File \"D:\\Anaconda3\\envs\\py39\\lib\\site-packages\\fastai\\basics.py\", line 1, in <module>\n",
      "    from .data.all import *\n",
      "  File \"D:\\Anaconda3\\envs\\py39\\lib\\site-packages\\fastai\\data\\all.py\", line 1, in <module>\n",
      "    from ..torch_basics import *\n",
      "  File \"D:\\Anaconda3\\envs\\py39\\lib\\site-packages\\fastai\\torch_basics.py\", line 1, in <module>\n",
      "    from torch import multiprocessing\n",
      "  File \"D:\\Anaconda3\\envs\\py39\\lib\\site-packages\\torch\\__init__.py\", line 124, in <module>\n",
      "    raise err\n",
      "OSError: [WinError 1455] 页面文件太小，无法完成操作。 Error loading \"D:\\Anaconda3\\envs\\py39\\lib\\site-packages\\torch\\lib\\caffe2_detectron_ops_gpu.dll\" or one of its dependencies.\n",
      "Detailed Traceback:\n",
      "Traceback (most recent call last):\n",
      "  File \"D:\\Anaconda3\\envs\\py39\\lib\\site-packages\\autogluon\\core\\trainer\\abstract_trainer.py\", line 1074, in _train_and_save\n",
      "    model = self._train_single(X, y, model, X_val, y_val, **model_fit_kwargs)\n",
      "  File \"D:\\Anaconda3\\envs\\py39\\lib\\site-packages\\autogluon\\core\\trainer\\abstract_trainer.py\", line 1032, in _train_single\n",
      "    model = model.fit(X=X, y=y, X_val=X_val, y_val=y_val, **model_fit_kwargs)\n",
      "  File \"D:\\Anaconda3\\envs\\py39\\lib\\site-packages\\autogluon\\core\\models\\abstract\\abstract_model.py\", line 577, in fit\n",
      "    out = self._fit(**kwargs)\n",
      "  File \"D:\\Anaconda3\\envs\\py39\\lib\\site-packages\\autogluon\\core\\models\\ensemble\\stacker_ensemble_model.py\", line 153, in _fit\n",
      "    return super()._fit(X=X, y=y, time_limit=time_limit, **kwargs)\n",
      "  File \"D:\\Anaconda3\\envs\\py39\\lib\\site-packages\\autogluon\\core\\models\\ensemble\\bagged_ensemble_model.py\", line 211, in _fit\n",
      "    self._fit_folds(X=X, y=y, model_base=model_base, X_pseudo=X_pseudo, y_pseudo=y_pseudo,\n",
      "  File \"D:\\Anaconda3\\envs\\py39\\lib\\site-packages\\autogluon\\core\\models\\ensemble\\bagged_ensemble_model.py\", line 481, in _fit_folds\n",
      "    fold_fitting_strategy.after_all_folds_scheduled()\n",
      "  File \"D:\\Anaconda3\\envs\\py39\\lib\\site-packages\\autogluon\\core\\models\\ensemble\\fold_fitting_strategy.py\", line 455, in after_all_folds_scheduled\n",
      "    raise processed_exception\n",
      "  File \"D:\\Anaconda3\\envs\\py39\\lib\\site-packages\\autogluon\\core\\models\\ensemble\\fold_fitting_strategy.py\", line 423, in after_all_folds_scheduled\n",
      "    time_end_fit, predict_time, predict_1_time = self.ray.get(finished)\n",
      "  File \"D:\\Anaconda3\\envs\\py39\\lib\\site-packages\\ray\\_private\\client_mode_hook.py\", line 89, in wrapper\n",
      "    return func(*args, **kwargs)\n",
      "  File \"D:\\Anaconda3\\envs\\py39\\lib\\site-packages\\ray\\worker.py\", line 1621, in get\n",
      "    raise value.as_instanceof_cause()\n",
      "ray.exceptions.RayTaskError(OSError): \u001b[36mray::_ray_fit()\u001b[39m (pid=30736, ip=192.168.1.5)\n",
      "  File \"python\\ray\\_raylet.pyx\", line 568, in ray._raylet.execute_task\n",
      "  File \"python\\ray\\_raylet.pyx\", line 572, in ray._raylet.execute_task\n",
      "  File \"D:\\Anaconda3\\envs\\py39\\lib\\site-packages\\autogluon\\core\\models\\ensemble\\fold_fitting_strategy.py\", line 288, in _ray_fit\n",
      "    fold_model.fit(X=X_fold, y=y_fold, X_val=X_val_fold, y_val=y_val_fold,\n",
      "  File \"D:\\Anaconda3\\envs\\py39\\lib\\site-packages\\autogluon\\core\\models\\abstract\\abstract_model.py\", line 577, in fit\n",
      "    out = self._fit(**kwargs)\n",
      "  File \"D:\\Anaconda3\\envs\\py39\\lib\\site-packages\\autogluon\\tabular\\models\\fastainn\\tabular_nn_fastai.py\", line 169, in _fit\n",
      "    try_import_fastai()\n",
      "  File \"D:\\Anaconda3\\envs\\py39\\lib\\site-packages\\autogluon\\core\\utils\\try_import.py\", line 128, in try_import_fastai\n",
      "    import autogluon.tabular.models.fastainn.imports_helper\n",
      "  File \"D:\\Anaconda3\\envs\\py39\\lib\\site-packages\\autogluon\\tabular\\models\\fastainn\\imports_helper.py\", line 1, in <module>\n",
      "    from fastai.tabular.all import *\n",
      "  File \"D:\\Anaconda3\\envs\\py39\\lib\\site-packages\\fastai\\tabular\\all.py\", line 1, in <module>\n",
      "    from ..basics import *\n",
      "  File \"D:\\Anaconda3\\envs\\py39\\lib\\site-packages\\fastai\\basics.py\", line 1, in <module>\n",
      "    from .data.all import *\n",
      "  File \"D:\\Anaconda3\\envs\\py39\\lib\\site-packages\\fastai\\data\\all.py\", line 1, in <module>\n",
      "    from ..torch_basics import *\n",
      "  File \"D:\\Anaconda3\\envs\\py39\\lib\\site-packages\\fastai\\torch_basics.py\", line 1, in <module>\n",
      "    from torch import multiprocessing\n",
      "  File \"D:\\Anaconda3\\envs\\py39\\lib\\site-packages\\torch\\__init__.py\", line 124, in <module>\n",
      "    raise err\n",
      "OSError: [WinError 1455] 页面文件太小，无法完成操作。 Error loading \"D:\\Anaconda3\\envs\\py39\\lib\\site-packages\\torch\\lib\\caffe2_detectron_ops_gpu.dll\" or one of its dependencies.\n"
     ]
    },
    {
     "name": "stderr",
     "output_type": "stream",
     "text": [
      "Fitting model: LightGBMXT_BAG_L1 ...\n",
      "\tFitting 8 child models (S1F1 - S1F8) | Fitting with ParallelLocalFoldFittingStrategy\n",
      "\tWarning: Exception caused LightGBMXT_BAG_L1 to fail during training... Skipping this model.\n",
      "\t\t\u001b[36mray::_ray_fit()\u001b[39m (pid=37836, ip=192.168.1.5)\n",
      "  File \"python\\ray\\_raylet.pyx\", line 568, in ray._raylet.execute_task\n",
      "  File \"python\\ray\\_raylet.pyx\", line 572, in ray._raylet.execute_task\n",
      "  File \"D:\\Anaconda3\\envs\\py39\\lib\\site-packages\\autogluon\\core\\models\\ensemble\\fold_fitting_strategy.py\", line 294, in _ray_fit\n",
      "    fold_model.save()\n",
      "  File \"D:\\Anaconda3\\envs\\py39\\lib\\site-packages\\autogluon\\core\\models\\abstract\\abstract_model.py\", line 764, in save\n",
      "    save_pkl.save(path=file_path, object=self, verbose=verbose)\n",
      "  File \"D:\\Anaconda3\\envs\\py39\\lib\\site-packages\\autogluon\\common\\savers\\save_pkl.py\", line 21, in save\n",
      "    save_with_fn(validated_path, object, pickle_fn, format=format, verbose=verbose, compression_fn=compression_fn,\n",
      "  File \"D:\\Anaconda3\\envs\\py39\\lib\\site-packages\\autogluon\\common\\savers\\save_pkl.py\", line 38, in save_with_fn\n",
      "    pickle_fn(object, fout)\n",
      "  File \"D:\\Anaconda3\\envs\\py39\\lib\\site-packages\\autogluon\\common\\savers\\save_pkl.py\", line 20, in <lambda>\n",
      "    pickle_fn = lambda o, buffer: pickle.dump(o, buffer, protocol=4)\n",
      "_pickle.PicklingError: Can't pickle <function macro_f1 at 0x000001B847AEFCA0>: attribute lookup macro_f1 on __main__ failed\n",
      "Detailed Traceback:\n",
      "Traceback (most recent call last):\n",
      "  File \"D:\\Anaconda3\\envs\\py39\\lib\\site-packages\\autogluon\\core\\trainer\\abstract_trainer.py\", line 1074, in _train_and_save\n",
      "    model = self._train_single(X, y, model, X_val, y_val, **model_fit_kwargs)\n",
      "  File \"D:\\Anaconda3\\envs\\py39\\lib\\site-packages\\autogluon\\core\\trainer\\abstract_trainer.py\", line 1032, in _train_single\n",
      "    model = model.fit(X=X, y=y, X_val=X_val, y_val=y_val, **model_fit_kwargs)\n",
      "  File \"D:\\Anaconda3\\envs\\py39\\lib\\site-packages\\autogluon\\core\\models\\abstract\\abstract_model.py\", line 577, in fit\n",
      "    out = self._fit(**kwargs)\n",
      "  File \"D:\\Anaconda3\\envs\\py39\\lib\\site-packages\\autogluon\\core\\models\\ensemble\\stacker_ensemble_model.py\", line 153, in _fit\n",
      "    return super()._fit(X=X, y=y, time_limit=time_limit, **kwargs)\n",
      "  File \"D:\\Anaconda3\\envs\\py39\\lib\\site-packages\\autogluon\\core\\models\\ensemble\\bagged_ensemble_model.py\", line 211, in _fit\n",
      "    self._fit_folds(X=X, y=y, model_base=model_base, X_pseudo=X_pseudo, y_pseudo=y_pseudo,\n",
      "  File \"D:\\Anaconda3\\envs\\py39\\lib\\site-packages\\autogluon\\core\\models\\ensemble\\bagged_ensemble_model.py\", line 481, in _fit_folds\n",
      "    fold_fitting_strategy.after_all_folds_scheduled()\n",
      "  File \"D:\\Anaconda3\\envs\\py39\\lib\\site-packages\\autogluon\\core\\models\\ensemble\\fold_fitting_strategy.py\", line 455, in after_all_folds_scheduled\n",
      "    raise processed_exception\n",
      "  File \"D:\\Anaconda3\\envs\\py39\\lib\\site-packages\\autogluon\\core\\models\\ensemble\\fold_fitting_strategy.py\", line 423, in after_all_folds_scheduled\n",
      "    time_end_fit, predict_time, predict_1_time = self.ray.get(finished)\n",
      "  File \"D:\\Anaconda3\\envs\\py39\\lib\\site-packages\\ray\\_private\\client_mode_hook.py\", line 89, in wrapper\n",
      "    return func(*args, **kwargs)\n",
      "  File \"D:\\Anaconda3\\envs\\py39\\lib\\site-packages\\ray\\worker.py\", line 1621, in get\n",
      "    raise value.as_instanceof_cause()\n",
      "ray.exceptions.RayTaskError(PicklingError): \u001b[36mray::_ray_fit()\u001b[39m (pid=37836, ip=192.168.1.5)\n",
      "  File \"python\\ray\\_raylet.pyx\", line 568, in ray._raylet.execute_task\n",
      "  File \"python\\ray\\_raylet.pyx\", line 572, in ray._raylet.execute_task\n",
      "  File \"D:\\Anaconda3\\envs\\py39\\lib\\site-packages\\autogluon\\core\\models\\ensemble\\fold_fitting_strategy.py\", line 294, in _ray_fit\n",
      "    fold_model.save()\n",
      "  File \"D:\\Anaconda3\\envs\\py39\\lib\\site-packages\\autogluon\\core\\models\\abstract\\abstract_model.py\", line 764, in save\n",
      "    save_pkl.save(path=file_path, object=self, verbose=verbose)\n",
      "  File \"D:\\Anaconda3\\envs\\py39\\lib\\site-packages\\autogluon\\common\\savers\\save_pkl.py\", line 21, in save\n",
      "    save_with_fn(validated_path, object, pickle_fn, format=format, verbose=verbose, compression_fn=compression_fn,\n",
      "  File \"D:\\Anaconda3\\envs\\py39\\lib\\site-packages\\autogluon\\common\\savers\\save_pkl.py\", line 38, in save_with_fn\n",
      "    pickle_fn(object, fout)\n",
      "  File \"D:\\Anaconda3\\envs\\py39\\lib\\site-packages\\autogluon\\common\\savers\\save_pkl.py\", line 20, in <lambda>\n",
      "    pickle_fn = lambda o, buffer: pickle.dump(o, buffer, protocol=4)\n",
      "_pickle.PicklingError: Can't pickle <function macro_f1 at 0x000001B847AEFCA0>: attribute lookup macro_f1 on __main__ failed\n",
      "Fitting model: LightGBM_BAG_L1 ...\n",
      "\tFitting 8 child models (S1F1 - S1F8) | Fitting with ParallelLocalFoldFittingStrategy\n",
      "\tWarning: Exception caused LightGBM_BAG_L1 to fail during training... Skipping this model.\n",
      "\t\t\u001b[36mray::_ray_fit()\u001b[39m (pid=50396, ip=192.168.1.5)\n",
      "  File \"python\\ray\\_raylet.pyx\", line 568, in ray._raylet.execute_task\n",
      "  File \"python\\ray\\_raylet.pyx\", line 572, in ray._raylet.execute_task\n",
      "  File \"D:\\Anaconda3\\envs\\py39\\lib\\site-packages\\autogluon\\core\\models\\ensemble\\fold_fitting_strategy.py\", line 294, in _ray_fit\n",
      "    fold_model.save()\n",
      "  File \"D:\\Anaconda3\\envs\\py39\\lib\\site-packages\\autogluon\\core\\models\\abstract\\abstract_model.py\", line 764, in save\n",
      "    save_pkl.save(path=file_path, object=self, verbose=verbose)\n",
      "  File \"D:\\Anaconda3\\envs\\py39\\lib\\site-packages\\autogluon\\common\\savers\\save_pkl.py\", line 21, in save\n",
      "    save_with_fn(validated_path, object, pickle_fn, format=format, verbose=verbose, compression_fn=compression_fn,\n",
      "  File \"D:\\Anaconda3\\envs\\py39\\lib\\site-packages\\autogluon\\common\\savers\\save_pkl.py\", line 38, in save_with_fn\n",
      "    pickle_fn(object, fout)\n",
      "  File \"D:\\Anaconda3\\envs\\py39\\lib\\site-packages\\autogluon\\common\\savers\\save_pkl.py\", line 20, in <lambda>\n",
      "    pickle_fn = lambda o, buffer: pickle.dump(o, buffer, protocol=4)\n",
      "_pickle.PicklingError: Can't pickle <function macro_f1 at 0x0000019B9816FCA0>: attribute lookup macro_f1 on __main__ failed\n",
      "Detailed Traceback:\n",
      "Traceback (most recent call last):\n",
      "  File \"D:\\Anaconda3\\envs\\py39\\lib\\site-packages\\autogluon\\core\\trainer\\abstract_trainer.py\", line 1074, in _train_and_save\n",
      "    model = self._train_single(X, y, model, X_val, y_val, **model_fit_kwargs)\n",
      "  File \"D:\\Anaconda3\\envs\\py39\\lib\\site-packages\\autogluon\\core\\trainer\\abstract_trainer.py\", line 1032, in _train_single\n",
      "    model = model.fit(X=X, y=y, X_val=X_val, y_val=y_val, **model_fit_kwargs)\n",
      "  File \"D:\\Anaconda3\\envs\\py39\\lib\\site-packages\\autogluon\\core\\models\\abstract\\abstract_model.py\", line 577, in fit\n",
      "    out = self._fit(**kwargs)\n",
      "  File \"D:\\Anaconda3\\envs\\py39\\lib\\site-packages\\autogluon\\core\\models\\ensemble\\stacker_ensemble_model.py\", line 153, in _fit\n",
      "    return super()._fit(X=X, y=y, time_limit=time_limit, **kwargs)\n",
      "  File \"D:\\Anaconda3\\envs\\py39\\lib\\site-packages\\autogluon\\core\\models\\ensemble\\bagged_ensemble_model.py\", line 211, in _fit\n",
      "    self._fit_folds(X=X, y=y, model_base=model_base, X_pseudo=X_pseudo, y_pseudo=y_pseudo,\n",
      "  File \"D:\\Anaconda3\\envs\\py39\\lib\\site-packages\\autogluon\\core\\models\\ensemble\\bagged_ensemble_model.py\", line 481, in _fit_folds\n",
      "    fold_fitting_strategy.after_all_folds_scheduled()\n",
      "  File \"D:\\Anaconda3\\envs\\py39\\lib\\site-packages\\autogluon\\core\\models\\ensemble\\fold_fitting_strategy.py\", line 455, in after_all_folds_scheduled\n",
      "    raise processed_exception\n",
      "  File \"D:\\Anaconda3\\envs\\py39\\lib\\site-packages\\autogluon\\core\\models\\ensemble\\fold_fitting_strategy.py\", line 423, in after_all_folds_scheduled\n",
      "    time_end_fit, predict_time, predict_1_time = self.ray.get(finished)\n",
      "  File \"D:\\Anaconda3\\envs\\py39\\lib\\site-packages\\ray\\_private\\client_mode_hook.py\", line 89, in wrapper\n",
      "    return func(*args, **kwargs)\n",
      "  File \"D:\\Anaconda3\\envs\\py39\\lib\\site-packages\\ray\\worker.py\", line 1621, in get\n",
      "    raise value.as_instanceof_cause()\n",
      "ray.exceptions.RayTaskError(PicklingError): \u001b[36mray::_ray_fit()\u001b[39m (pid=50396, ip=192.168.1.5)\n",
      "  File \"python\\ray\\_raylet.pyx\", line 568, in ray._raylet.execute_task\n",
      "  File \"python\\ray\\_raylet.pyx\", line 572, in ray._raylet.execute_task\n",
      "  File \"D:\\Anaconda3\\envs\\py39\\lib\\site-packages\\autogluon\\core\\models\\ensemble\\fold_fitting_strategy.py\", line 294, in _ray_fit\n",
      "    fold_model.save()\n",
      "  File \"D:\\Anaconda3\\envs\\py39\\lib\\site-packages\\autogluon\\core\\models\\abstract\\abstract_model.py\", line 764, in save\n",
      "    save_pkl.save(path=file_path, object=self, verbose=verbose)\n",
      "  File \"D:\\Anaconda3\\envs\\py39\\lib\\site-packages\\autogluon\\common\\savers\\save_pkl.py\", line 21, in save\n",
      "    save_with_fn(validated_path, object, pickle_fn, format=format, verbose=verbose, compression_fn=compression_fn,\n",
      "  File \"D:\\Anaconda3\\envs\\py39\\lib\\site-packages\\autogluon\\common\\savers\\save_pkl.py\", line 38, in save_with_fn\n",
      "    pickle_fn(object, fout)\n",
      "  File \"D:\\Anaconda3\\envs\\py39\\lib\\site-packages\\autogluon\\common\\savers\\save_pkl.py\", line 20, in <lambda>\n",
      "    pickle_fn = lambda o, buffer: pickle.dump(o, buffer, protocol=4)\n",
      "_pickle.PicklingError: Can't pickle <function macro_f1 at 0x0000019B9816FCA0>: attribute lookup macro_f1 on __main__ failed\n"
     ]
    },
    {
     "name": "stderr",
     "output_type": "stream",
     "text": [
      "Fitting model: RandomForestGini_BAG_L1 ...\n",
      "\t0.6099\t = Validation score   (macro_f1)\n",
      "\t5.65s\t = Training   runtime\n",
      "\t6.93s\t = Validation runtime\n",
      "Fitting model: RandomForestEntr_BAG_L1 ...\n",
      "\t0.6103\t = Validation score   (macro_f1)\n",
      "\t5.51s\t = Training   runtime\n",
      "\t7.15s\t = Validation runtime\n",
      "Fitting model: CatBoost_BAG_L1 ...\n",
      "\tFitting 8 child models (S1F1 - S1F8) | Fitting with ParallelLocalFoldFittingStrategy\n",
      "\tWarning: Exception caused CatBoost_BAG_L1 to fail during training... Skipping this model.\n",
      "\t\t\u001b[36mray::_ray_fit()\u001b[39m (pid=55276, ip=192.168.1.5)\n",
      "  File \"python\\ray\\_raylet.pyx\", line 568, in ray._raylet.execute_task\n",
      "  File \"python\\ray\\_raylet.pyx\", line 572, in ray._raylet.execute_task\n",
      "  File \"D:\\Anaconda3\\envs\\py39\\lib\\site-packages\\autogluon\\core\\models\\ensemble\\fold_fitting_strategy.py\", line 294, in _ray_fit\n",
      "    fold_model.save()\n",
      "  File \"D:\\Anaconda3\\envs\\py39\\lib\\site-packages\\autogluon\\core\\models\\abstract\\abstract_model.py\", line 764, in save\n",
      "    save_pkl.save(path=file_path, object=self, verbose=verbose)\n",
      "  File \"D:\\Anaconda3\\envs\\py39\\lib\\site-packages\\autogluon\\common\\savers\\save_pkl.py\", line 21, in save\n",
      "    save_with_fn(validated_path, object, pickle_fn, format=format, verbose=verbose, compression_fn=compression_fn,\n",
      "  File \"D:\\Anaconda3\\envs\\py39\\lib\\site-packages\\autogluon\\common\\savers\\save_pkl.py\", line 38, in save_with_fn\n",
      "    pickle_fn(object, fout)\n",
      "  File \"D:\\Anaconda3\\envs\\py39\\lib\\site-packages\\autogluon\\common\\savers\\save_pkl.py\", line 20, in <lambda>\n",
      "    pickle_fn = lambda o, buffer: pickle.dump(o, buffer, protocol=4)\n",
      "_pickle.PicklingError: Can't pickle <function macro_f1 at 0x0000020D8E35FCA0>: attribute lookup macro_f1 on __main__ failed\n",
      "Detailed Traceback:\n",
      "Traceback (most recent call last):\n",
      "  File \"D:\\Anaconda3\\envs\\py39\\lib\\site-packages\\autogluon\\core\\trainer\\abstract_trainer.py\", line 1074, in _train_and_save\n",
      "    model = self._train_single(X, y, model, X_val, y_val, **model_fit_kwargs)\n",
      "  File \"D:\\Anaconda3\\envs\\py39\\lib\\site-packages\\autogluon\\core\\trainer\\abstract_trainer.py\", line 1032, in _train_single\n",
      "    model = model.fit(X=X, y=y, X_val=X_val, y_val=y_val, **model_fit_kwargs)\n",
      "  File \"D:\\Anaconda3\\envs\\py39\\lib\\site-packages\\autogluon\\core\\models\\abstract\\abstract_model.py\", line 577, in fit\n",
      "    out = self._fit(**kwargs)\n",
      "  File \"D:\\Anaconda3\\envs\\py39\\lib\\site-packages\\autogluon\\core\\models\\ensemble\\stacker_ensemble_model.py\", line 153, in _fit\n",
      "    return super()._fit(X=X, y=y, time_limit=time_limit, **kwargs)\n",
      "  File \"D:\\Anaconda3\\envs\\py39\\lib\\site-packages\\autogluon\\core\\models\\ensemble\\bagged_ensemble_model.py\", line 211, in _fit\n",
      "    self._fit_folds(X=X, y=y, model_base=model_base, X_pseudo=X_pseudo, y_pseudo=y_pseudo,\n",
      "  File \"D:\\Anaconda3\\envs\\py39\\lib\\site-packages\\autogluon\\core\\models\\ensemble\\bagged_ensemble_model.py\", line 481, in _fit_folds\n",
      "    fold_fitting_strategy.after_all_folds_scheduled()\n",
      "  File \"D:\\Anaconda3\\envs\\py39\\lib\\site-packages\\autogluon\\core\\models\\ensemble\\fold_fitting_strategy.py\", line 455, in after_all_folds_scheduled\n",
      "    raise processed_exception\n",
      "  File \"D:\\Anaconda3\\envs\\py39\\lib\\site-packages\\autogluon\\core\\models\\ensemble\\fold_fitting_strategy.py\", line 423, in after_all_folds_scheduled\n",
      "    time_end_fit, predict_time, predict_1_time = self.ray.get(finished)\n",
      "  File \"D:\\Anaconda3\\envs\\py39\\lib\\site-packages\\ray\\_private\\client_mode_hook.py\", line 89, in wrapper\n",
      "    return func(*args, **kwargs)\n",
      "  File \"D:\\Anaconda3\\envs\\py39\\lib\\site-packages\\ray\\worker.py\", line 1621, in get\n",
      "    raise value.as_instanceof_cause()\n",
      "ray.exceptions.RayTaskError(PicklingError): \u001b[36mray::_ray_fit()\u001b[39m (pid=55276, ip=192.168.1.5)\n",
      "  File \"python\\ray\\_raylet.pyx\", line 568, in ray._raylet.execute_task\n",
      "  File \"python\\ray\\_raylet.pyx\", line 572, in ray._raylet.execute_task\n",
      "  File \"D:\\Anaconda3\\envs\\py39\\lib\\site-packages\\autogluon\\core\\models\\ensemble\\fold_fitting_strategy.py\", line 294, in _ray_fit\n",
      "    fold_model.save()\n",
      "  File \"D:\\Anaconda3\\envs\\py39\\lib\\site-packages\\autogluon\\core\\models\\abstract\\abstract_model.py\", line 764, in save\n",
      "    save_pkl.save(path=file_path, object=self, verbose=verbose)\n",
      "  File \"D:\\Anaconda3\\envs\\py39\\lib\\site-packages\\autogluon\\common\\savers\\save_pkl.py\", line 21, in save\n",
      "    save_with_fn(validated_path, object, pickle_fn, format=format, verbose=verbose, compression_fn=compression_fn,\n",
      "  File \"D:\\Anaconda3\\envs\\py39\\lib\\site-packages\\autogluon\\common\\savers\\save_pkl.py\", line 38, in save_with_fn\n",
      "    pickle_fn(object, fout)\n",
      "  File \"D:\\Anaconda3\\envs\\py39\\lib\\site-packages\\autogluon\\common\\savers\\save_pkl.py\", line 20, in <lambda>\n",
      "    pickle_fn = lambda o, buffer: pickle.dump(o, buffer, protocol=4)\n",
      "_pickle.PicklingError: Can't pickle <function macro_f1 at 0x0000020D8E35FCA0>: attribute lookup macro_f1 on __main__ failed\n",
      "Fitting model: ExtraTreesGini_BAG_L1 ...\n",
      "\t0.6078\t = Validation score   (macro_f1)\n",
      "\t4.99s\t = Training   runtime\n",
      "\t6.48s\t = Validation runtime\n",
      "Fitting model: ExtraTreesEntr_BAG_L1 ...\n",
      "\t0.6098\t = Validation score   (macro_f1)\n",
      "\t5.02s\t = Training   runtime\n",
      "\t6.62s\t = Validation runtime\n",
      "Fitting model: XGBoost_BAG_L1 ...\n",
      "\tFitting 8 child models (S1F1 - S1F8) | Fitting with ParallelLocalFoldFittingStrategy\n",
      "\tWarning: Exception caused XGBoost_BAG_L1 to fail during training... Skipping this model.\n",
      "\t\t\u001b[36mray::_ray_fit()\u001b[39m (pid=47168, ip=192.168.1.5)\n",
      "  File \"python\\ray\\_raylet.pyx\", line 568, in ray._raylet.execute_task\n",
      "  File \"python\\ray\\_raylet.pyx\", line 572, in ray._raylet.execute_task\n",
      "  File \"D:\\Anaconda3\\envs\\py39\\lib\\site-packages\\autogluon\\core\\models\\ensemble\\fold_fitting_strategy.py\", line 294, in _ray_fit\n",
      "    fold_model.save()\n",
      "  File \"D:\\Anaconda3\\envs\\py39\\lib\\site-packages\\autogluon\\tabular\\models\\xgboost\\xgboost_model.py\", line 209, in save\n",
      "    path = super().save(path=path, verbose=verbose)\n",
      "  File \"D:\\Anaconda3\\envs\\py39\\lib\\site-packages\\autogluon\\core\\models\\abstract\\abstract_model.py\", line 764, in save\n",
      "    save_pkl.save(path=file_path, object=self, verbose=verbose)\n",
      "  File \"D:\\Anaconda3\\envs\\py39\\lib\\site-packages\\autogluon\\common\\savers\\save_pkl.py\", line 21, in save\n",
      "    save_with_fn(validated_path, object, pickle_fn, format=format, verbose=verbose, compression_fn=compression_fn,\n",
      "  File \"D:\\Anaconda3\\envs\\py39\\lib\\site-packages\\autogluon\\common\\savers\\save_pkl.py\", line 38, in save_with_fn\n",
      "    pickle_fn(object, fout)\n",
      "  File \"D:\\Anaconda3\\envs\\py39\\lib\\site-packages\\autogluon\\common\\savers\\save_pkl.py\", line 20, in <lambda>\n",
      "    pickle_fn = lambda o, buffer: pickle.dump(o, buffer, protocol=4)\n",
      "_pickle.PicklingError: Can't pickle <function macro_f1 at 0x000001CC6250FCA0>: attribute lookup macro_f1 on __main__ failed\n",
      "Detailed Traceback:\n",
      "Traceback (most recent call last):\n",
      "  File \"D:\\Anaconda3\\envs\\py39\\lib\\site-packages\\autogluon\\core\\trainer\\abstract_trainer.py\", line 1074, in _train_and_save\n",
      "    model = self._train_single(X, y, model, X_val, y_val, **model_fit_kwargs)\n",
      "  File \"D:\\Anaconda3\\envs\\py39\\lib\\site-packages\\autogluon\\core\\trainer\\abstract_trainer.py\", line 1032, in _train_single\n",
      "    model = model.fit(X=X, y=y, X_val=X_val, y_val=y_val, **model_fit_kwargs)\n",
      "  File \"D:\\Anaconda3\\envs\\py39\\lib\\site-packages\\autogluon\\core\\models\\abstract\\abstract_model.py\", line 577, in fit\n",
      "    out = self._fit(**kwargs)\n",
      "  File \"D:\\Anaconda3\\envs\\py39\\lib\\site-packages\\autogluon\\core\\models\\ensemble\\stacker_ensemble_model.py\", line 153, in _fit\n",
      "    return super()._fit(X=X, y=y, time_limit=time_limit, **kwargs)\n",
      "  File \"D:\\Anaconda3\\envs\\py39\\lib\\site-packages\\autogluon\\core\\models\\ensemble\\bagged_ensemble_model.py\", line 211, in _fit\n",
      "    self._fit_folds(X=X, y=y, model_base=model_base, X_pseudo=X_pseudo, y_pseudo=y_pseudo,\n",
      "  File \"D:\\Anaconda3\\envs\\py39\\lib\\site-packages\\autogluon\\core\\models\\ensemble\\bagged_ensemble_model.py\", line 481, in _fit_folds\n",
      "    fold_fitting_strategy.after_all_folds_scheduled()\n",
      "  File \"D:\\Anaconda3\\envs\\py39\\lib\\site-packages\\autogluon\\core\\models\\ensemble\\fold_fitting_strategy.py\", line 455, in after_all_folds_scheduled\n",
      "    raise processed_exception\n",
      "  File \"D:\\Anaconda3\\envs\\py39\\lib\\site-packages\\autogluon\\core\\models\\ensemble\\fold_fitting_strategy.py\", line 423, in after_all_folds_scheduled\n",
      "    time_end_fit, predict_time, predict_1_time = self.ray.get(finished)\n",
      "  File \"D:\\Anaconda3\\envs\\py39\\lib\\site-packages\\ray\\_private\\client_mode_hook.py\", line 89, in wrapper\n",
      "    return func(*args, **kwargs)\n",
      "  File \"D:\\Anaconda3\\envs\\py39\\lib\\site-packages\\ray\\worker.py\", line 1621, in get\n",
      "    raise value.as_instanceof_cause()\n",
      "ray.exceptions.RayTaskError(PicklingError): \u001b[36mray::_ray_fit()\u001b[39m (pid=47168, ip=192.168.1.5)\n",
      "  File \"python\\ray\\_raylet.pyx\", line 568, in ray._raylet.execute_task\n",
      "  File \"python\\ray\\_raylet.pyx\", line 572, in ray._raylet.execute_task\n",
      "  File \"D:\\Anaconda3\\envs\\py39\\lib\\site-packages\\autogluon\\core\\models\\ensemble\\fold_fitting_strategy.py\", line 294, in _ray_fit\n",
      "    fold_model.save()\n",
      "  File \"D:\\Anaconda3\\envs\\py39\\lib\\site-packages\\autogluon\\tabular\\models\\xgboost\\xgboost_model.py\", line 209, in save\n",
      "    path = super().save(path=path, verbose=verbose)\n",
      "  File \"D:\\Anaconda3\\envs\\py39\\lib\\site-packages\\autogluon\\core\\models\\abstract\\abstract_model.py\", line 764, in save\n",
      "    save_pkl.save(path=file_path, object=self, verbose=verbose)\n",
      "  File \"D:\\Anaconda3\\envs\\py39\\lib\\site-packages\\autogluon\\common\\savers\\save_pkl.py\", line 21, in save\n",
      "    save_with_fn(validated_path, object, pickle_fn, format=format, verbose=verbose, compression_fn=compression_fn,\n",
      "  File \"D:\\Anaconda3\\envs\\py39\\lib\\site-packages\\autogluon\\common\\savers\\save_pkl.py\", line 38, in save_with_fn\n",
      "    pickle_fn(object, fout)\n",
      "  File \"D:\\Anaconda3\\envs\\py39\\lib\\site-packages\\autogluon\\common\\savers\\save_pkl.py\", line 20, in <lambda>\n",
      "    pickle_fn = lambda o, buffer: pickle.dump(o, buffer, protocol=4)\n",
      "_pickle.PicklingError: Can't pickle <function macro_f1 at 0x000001CC6250FCA0>: attribute lookup macro_f1 on __main__ failed\n"
     ]
    },
    {
     "name": "stderr",
     "output_type": "stream",
     "text": [
      "Fitting model: NeuralNetTorch_BAG_L1 ...\n",
      "\tFitting 8 child models (S1F1 - S1F8) | Fitting with ParallelLocalFoldFittingStrategy\n",
      "\tWarning: Exception caused NeuralNetTorch_BAG_L1 to fail during training... Skipping this model.\n",
      "\t\t\u001b[36mray::_ray_fit()\u001b[39m (pid=16688, ip=192.168.1.5)\n",
      "  File \"python\\ray\\_raylet.pyx\", line 568, in ray._raylet.execute_task\n",
      "  File \"python\\ray\\_raylet.pyx\", line 572, in ray._raylet.execute_task\n",
      "  File \"D:\\Anaconda3\\envs\\py39\\lib\\site-packages\\autogluon\\core\\models\\ensemble\\fold_fitting_strategy.py\", line 288, in _ray_fit\n",
      "    fold_model.fit(X=X_fold, y=y_fold, X_val=X_val_fold, y_val=y_val_fold,\n",
      "  File \"D:\\Anaconda3\\envs\\py39\\lib\\site-packages\\autogluon\\core\\models\\abstract\\abstract_model.py\", line 577, in fit\n",
      "    out = self._fit(**kwargs)\n",
      "  File \"D:\\Anaconda3\\envs\\py39\\lib\\site-packages\\autogluon\\tabular\\models\\tabular_nn\\torch\\tabular_nn_torch.py\", line 140, in _fit\n",
      "    try_import_torch()\n",
      "  File \"D:\\Anaconda3\\envs\\py39\\lib\\site-packages\\autogluon\\core\\utils\\try_import.py\", line 146, in try_import_torch\n",
      "    import torch\n",
      "  File \"D:\\Anaconda3\\envs\\py39\\lib\\site-packages\\torch\\__init__.py\", line 124, in <module>\n",
      "    raise err\n",
      "OSError: [WinError 1455] 页面文件太小，无法完成操作。 Error loading \"D:\\Anaconda3\\envs\\py39\\lib\\site-packages\\torch\\lib\\cudnn_cnn_infer64_8.dll\" or one of its dependencies.\n",
      "Detailed Traceback:\n",
      "Traceback (most recent call last):\n",
      "  File \"D:\\Anaconda3\\envs\\py39\\lib\\site-packages\\autogluon\\core\\trainer\\abstract_trainer.py\", line 1074, in _train_and_save\n",
      "    model = self._train_single(X, y, model, X_val, y_val, **model_fit_kwargs)\n",
      "  File \"D:\\Anaconda3\\envs\\py39\\lib\\site-packages\\autogluon\\core\\trainer\\abstract_trainer.py\", line 1032, in _train_single\n",
      "    model = model.fit(X=X, y=y, X_val=X_val, y_val=y_val, **model_fit_kwargs)\n",
      "  File \"D:\\Anaconda3\\envs\\py39\\lib\\site-packages\\autogluon\\core\\models\\abstract\\abstract_model.py\", line 577, in fit\n",
      "    out = self._fit(**kwargs)\n",
      "  File \"D:\\Anaconda3\\envs\\py39\\lib\\site-packages\\autogluon\\core\\models\\ensemble\\stacker_ensemble_model.py\", line 153, in _fit\n",
      "    return super()._fit(X=X, y=y, time_limit=time_limit, **kwargs)\n",
      "  File \"D:\\Anaconda3\\envs\\py39\\lib\\site-packages\\autogluon\\core\\models\\ensemble\\bagged_ensemble_model.py\", line 211, in _fit\n",
      "    self._fit_folds(X=X, y=y, model_base=model_base, X_pseudo=X_pseudo, y_pseudo=y_pseudo,\n",
      "  File \"D:\\Anaconda3\\envs\\py39\\lib\\site-packages\\autogluon\\core\\models\\ensemble\\bagged_ensemble_model.py\", line 481, in _fit_folds\n",
      "    fold_fitting_strategy.after_all_folds_scheduled()\n",
      "  File \"D:\\Anaconda3\\envs\\py39\\lib\\site-packages\\autogluon\\core\\models\\ensemble\\fold_fitting_strategy.py\", line 455, in after_all_folds_scheduled\n",
      "    raise processed_exception\n",
      "  File \"D:\\Anaconda3\\envs\\py39\\lib\\site-packages\\autogluon\\core\\models\\ensemble\\fold_fitting_strategy.py\", line 423, in after_all_folds_scheduled\n",
      "    time_end_fit, predict_time, predict_1_time = self.ray.get(finished)\n",
      "  File \"D:\\Anaconda3\\envs\\py39\\lib\\site-packages\\ray\\_private\\client_mode_hook.py\", line 89, in wrapper\n",
      "    return func(*args, **kwargs)\n",
      "  File \"D:\\Anaconda3\\envs\\py39\\lib\\site-packages\\ray\\worker.py\", line 1621, in get\n",
      "    raise value.as_instanceof_cause()\n",
      "ray.exceptions.RayTaskError(OSError): \u001b[36mray::_ray_fit()\u001b[39m (pid=16688, ip=192.168.1.5)\n",
      "  File \"python\\ray\\_raylet.pyx\", line 568, in ray._raylet.execute_task\n",
      "  File \"python\\ray\\_raylet.pyx\", line 572, in ray._raylet.execute_task\n",
      "  File \"D:\\Anaconda3\\envs\\py39\\lib\\site-packages\\autogluon\\core\\models\\ensemble\\fold_fitting_strategy.py\", line 288, in _ray_fit\n",
      "    fold_model.fit(X=X_fold, y=y_fold, X_val=X_val_fold, y_val=y_val_fold,\n",
      "  File \"D:\\Anaconda3\\envs\\py39\\lib\\site-packages\\autogluon\\core\\models\\abstract\\abstract_model.py\", line 577, in fit\n",
      "    out = self._fit(**kwargs)\n",
      "  File \"D:\\Anaconda3\\envs\\py39\\lib\\site-packages\\autogluon\\tabular\\models\\tabular_nn\\torch\\tabular_nn_torch.py\", line 140, in _fit\n",
      "    try_import_torch()\n",
      "  File \"D:\\Anaconda3\\envs\\py39\\lib\\site-packages\\autogluon\\core\\utils\\try_import.py\", line 146, in try_import_torch\n",
      "    import torch\n",
      "  File \"D:\\Anaconda3\\envs\\py39\\lib\\site-packages\\torch\\__init__.py\", line 124, in <module>\n",
      "    raise err\n",
      "OSError: [WinError 1455] 页面文件太小，无法完成操作。 Error loading \"D:\\Anaconda3\\envs\\py39\\lib\\site-packages\\torch\\lib\\cudnn_cnn_infer64_8.dll\" or one of its dependencies.\n",
      "Fitting model: LightGBMLarge_BAG_L1 ...\n",
      "\tFitting 8 child models (S1F1 - S1F8) | Fitting with ParallelLocalFoldFittingStrategy\n",
      "\tWarning: Exception caused LightGBMLarge_BAG_L1 to fail during training... Skipping this model.\n",
      "\t\t\u001b[36mray::_ray_fit()\u001b[39m (pid=40084, ip=192.168.1.5)\n",
      "  File \"python\\ray\\_raylet.pyx\", line 568, in ray._raylet.execute_task\n",
      "  File \"python\\ray\\_raylet.pyx\", line 572, in ray._raylet.execute_task\n",
      "  File \"D:\\Anaconda3\\envs\\py39\\lib\\site-packages\\autogluon\\core\\models\\ensemble\\fold_fitting_strategy.py\", line 294, in _ray_fit\n",
      "    fold_model.save()\n",
      "  File \"D:\\Anaconda3\\envs\\py39\\lib\\site-packages\\autogluon\\core\\models\\abstract\\abstract_model.py\", line 764, in save\n",
      "    save_pkl.save(path=file_path, object=self, verbose=verbose)\n",
      "  File \"D:\\Anaconda3\\envs\\py39\\lib\\site-packages\\autogluon\\common\\savers\\save_pkl.py\", line 21, in save\n",
      "    save_with_fn(validated_path, object, pickle_fn, format=format, verbose=verbose, compression_fn=compression_fn,\n",
      "  File \"D:\\Anaconda3\\envs\\py39\\lib\\site-packages\\autogluon\\common\\savers\\save_pkl.py\", line 38, in save_with_fn\n",
      "    pickle_fn(object, fout)\n",
      "  File \"D:\\Anaconda3\\envs\\py39\\lib\\site-packages\\autogluon\\common\\savers\\save_pkl.py\", line 20, in <lambda>\n",
      "    pickle_fn = lambda o, buffer: pickle.dump(o, buffer, protocol=4)\n",
      "_pickle.PicklingError: Can't pickle <function macro_f1 at 0x000001C31A48FCA0>: attribute lookup macro_f1 on __main__ failed\n",
      "Detailed Traceback:\n",
      "Traceback (most recent call last):\n",
      "  File \"D:\\Anaconda3\\envs\\py39\\lib\\site-packages\\autogluon\\core\\trainer\\abstract_trainer.py\", line 1074, in _train_and_save\n",
      "    model = self._train_single(X, y, model, X_val, y_val, **model_fit_kwargs)\n",
      "  File \"D:\\Anaconda3\\envs\\py39\\lib\\site-packages\\autogluon\\core\\trainer\\abstract_trainer.py\", line 1032, in _train_single\n",
      "    model = model.fit(X=X, y=y, X_val=X_val, y_val=y_val, **model_fit_kwargs)\n",
      "  File \"D:\\Anaconda3\\envs\\py39\\lib\\site-packages\\autogluon\\core\\models\\abstract\\abstract_model.py\", line 577, in fit\n",
      "    out = self._fit(**kwargs)\n",
      "  File \"D:\\Anaconda3\\envs\\py39\\lib\\site-packages\\autogluon\\core\\models\\ensemble\\stacker_ensemble_model.py\", line 153, in _fit\n",
      "    return super()._fit(X=X, y=y, time_limit=time_limit, **kwargs)\n",
      "  File \"D:\\Anaconda3\\envs\\py39\\lib\\site-packages\\autogluon\\core\\models\\ensemble\\bagged_ensemble_model.py\", line 211, in _fit\n",
      "    self._fit_folds(X=X, y=y, model_base=model_base, X_pseudo=X_pseudo, y_pseudo=y_pseudo,\n",
      "  File \"D:\\Anaconda3\\envs\\py39\\lib\\site-packages\\autogluon\\core\\models\\ensemble\\bagged_ensemble_model.py\", line 481, in _fit_folds\n",
      "    fold_fitting_strategy.after_all_folds_scheduled()\n",
      "  File \"D:\\Anaconda3\\envs\\py39\\lib\\site-packages\\autogluon\\core\\models\\ensemble\\fold_fitting_strategy.py\", line 455, in after_all_folds_scheduled\n",
      "    raise processed_exception\n",
      "  File \"D:\\Anaconda3\\envs\\py39\\lib\\site-packages\\autogluon\\core\\models\\ensemble\\fold_fitting_strategy.py\", line 423, in after_all_folds_scheduled\n",
      "    time_end_fit, predict_time, predict_1_time = self.ray.get(finished)\n",
      "  File \"D:\\Anaconda3\\envs\\py39\\lib\\site-packages\\ray\\_private\\client_mode_hook.py\", line 89, in wrapper\n",
      "    return func(*args, **kwargs)\n",
      "  File \"D:\\Anaconda3\\envs\\py39\\lib\\site-packages\\ray\\worker.py\", line 1621, in get\n",
      "    raise value.as_instanceof_cause()\n",
      "ray.exceptions.RayTaskError(PicklingError): \u001b[36mray::_ray_fit()\u001b[39m (pid=40084, ip=192.168.1.5)\n",
      "  File \"python\\ray\\_raylet.pyx\", line 568, in ray._raylet.execute_task\n",
      "  File \"python\\ray\\_raylet.pyx\", line 572, in ray._raylet.execute_task\n",
      "  File \"D:\\Anaconda3\\envs\\py39\\lib\\site-packages\\autogluon\\core\\models\\ensemble\\fold_fitting_strategy.py\", line 294, in _ray_fit\n",
      "    fold_model.save()\n",
      "  File \"D:\\Anaconda3\\envs\\py39\\lib\\site-packages\\autogluon\\core\\models\\abstract\\abstract_model.py\", line 764, in save\n",
      "    save_pkl.save(path=file_path, object=self, verbose=verbose)\n",
      "  File \"D:\\Anaconda3\\envs\\py39\\lib\\site-packages\\autogluon\\common\\savers\\save_pkl.py\", line 21, in save\n",
      "    save_with_fn(validated_path, object, pickle_fn, format=format, verbose=verbose, compression_fn=compression_fn,\n",
      "  File \"D:\\Anaconda3\\envs\\py39\\lib\\site-packages\\autogluon\\common\\savers\\save_pkl.py\", line 38, in save_with_fn\n",
      "    pickle_fn(object, fout)\n",
      "  File \"D:\\Anaconda3\\envs\\py39\\lib\\site-packages\\autogluon\\common\\savers\\save_pkl.py\", line 20, in <lambda>\n",
      "    pickle_fn = lambda o, buffer: pickle.dump(o, buffer, protocol=4)\n",
      "_pickle.PicklingError: Can't pickle <function macro_f1 at 0x000001C31A48FCA0>: attribute lookup macro_f1 on __main__ failed\n"
     ]
    },
    {
     "name": "stderr",
     "output_type": "stream",
     "text": [
      "Fitting model: WeightedEnsemble_L2 ...\n",
      "\t0.6134\t = Validation score   (macro_f1)\n",
      "\t5.08s\t = Training   runtime\n",
      "\t0.01s\t = Validation runtime\n",
      "Fitting 11 L2 models ...\n",
      "Fitting model: NeuralNetFastAI_BAG_L2 ...\n",
      "\tFitting 8 child models (S1F1 - S1F8) | Fitting with ParallelLocalFoldFittingStrategy\n",
      "\tWarning: Exception caused NeuralNetFastAI_BAG_L2 to fail during training... Skipping this model.\n",
      "\t\t\u001b[36mray::_ray_fit()\u001b[39m (pid=40888, ip=192.168.1.5)\n",
      "  File \"python\\ray\\_raylet.pyx\", line 568, in ray._raylet.execute_task\n",
      "  File \"python\\ray\\_raylet.pyx\", line 572, in ray._raylet.execute_task\n",
      "  File \"D:\\Anaconda3\\envs\\py39\\lib\\site-packages\\autogluon\\core\\models\\ensemble\\fold_fitting_strategy.py\", line 288, in _ray_fit\n",
      "    fold_model.fit(X=X_fold, y=y_fold, X_val=X_val_fold, y_val=y_val_fold,\n",
      "  File \"D:\\Anaconda3\\envs\\py39\\lib\\site-packages\\autogluon\\core\\models\\abstract\\abstract_model.py\", line 577, in fit\n",
      "    out = self._fit(**kwargs)\n",
      "  File \"D:\\Anaconda3\\envs\\py39\\lib\\site-packages\\autogluon\\tabular\\models\\fastainn\\tabular_nn_fastai.py\", line 169, in _fit\n",
      "    try_import_fastai()\n",
      "  File \"D:\\Anaconda3\\envs\\py39\\lib\\site-packages\\autogluon\\core\\utils\\try_import.py\", line 128, in try_import_fastai\n",
      "    import autogluon.tabular.models.fastainn.imports_helper\n",
      "  File \"D:\\Anaconda3\\envs\\py39\\lib\\site-packages\\autogluon\\tabular\\models\\fastainn\\imports_helper.py\", line 1, in <module>\n",
      "    from fastai.tabular.all import *\n",
      "  File \"D:\\Anaconda3\\envs\\py39\\lib\\site-packages\\fastai\\tabular\\all.py\", line 1, in <module>\n",
      "    from ..basics import *\n",
      "  File \"D:\\Anaconda3\\envs\\py39\\lib\\site-packages\\fastai\\basics.py\", line 1, in <module>\n",
      "    from .data.all import *\n",
      "  File \"D:\\Anaconda3\\envs\\py39\\lib\\site-packages\\fastai\\data\\all.py\", line 1, in <module>\n",
      "    from ..torch_basics import *\n",
      "  File \"D:\\Anaconda3\\envs\\py39\\lib\\site-packages\\fastai\\torch_basics.py\", line 1, in <module>\n",
      "    from torch import multiprocessing\n",
      "  File \"D:\\Anaconda3\\envs\\py39\\lib\\site-packages\\torch\\__init__.py\", line 124, in <module>\n",
      "    raise err\n",
      "OSError: [WinError 1455] 页面文件太小，无法完成操作。 Error loading \"D:\\Anaconda3\\envs\\py39\\lib\\site-packages\\torch\\lib\\cudnn_cnn_infer64_8.dll\" or one of its dependencies.\n",
      "Detailed Traceback:\n",
      "Traceback (most recent call last):\n",
      "  File \"D:\\Anaconda3\\envs\\py39\\lib\\site-packages\\autogluon\\core\\trainer\\abstract_trainer.py\", line 1074, in _train_and_save\n",
      "    model = self._train_single(X, y, model, X_val, y_val, **model_fit_kwargs)\n",
      "  File \"D:\\Anaconda3\\envs\\py39\\lib\\site-packages\\autogluon\\core\\trainer\\abstract_trainer.py\", line 1032, in _train_single\n",
      "    model = model.fit(X=X, y=y, X_val=X_val, y_val=y_val, **model_fit_kwargs)\n",
      "  File \"D:\\Anaconda3\\envs\\py39\\lib\\site-packages\\autogluon\\core\\models\\abstract\\abstract_model.py\", line 577, in fit\n",
      "    out = self._fit(**kwargs)\n",
      "  File \"D:\\Anaconda3\\envs\\py39\\lib\\site-packages\\autogluon\\core\\models\\ensemble\\stacker_ensemble_model.py\", line 153, in _fit\n",
      "    return super()._fit(X=X, y=y, time_limit=time_limit, **kwargs)\n",
      "  File \"D:\\Anaconda3\\envs\\py39\\lib\\site-packages\\autogluon\\core\\models\\ensemble\\bagged_ensemble_model.py\", line 211, in _fit\n",
      "    self._fit_folds(X=X, y=y, model_base=model_base, X_pseudo=X_pseudo, y_pseudo=y_pseudo,\n",
      "  File \"D:\\Anaconda3\\envs\\py39\\lib\\site-packages\\autogluon\\core\\models\\ensemble\\bagged_ensemble_model.py\", line 481, in _fit_folds\n",
      "    fold_fitting_strategy.after_all_folds_scheduled()\n",
      "  File \"D:\\Anaconda3\\envs\\py39\\lib\\site-packages\\autogluon\\core\\models\\ensemble\\fold_fitting_strategy.py\", line 455, in after_all_folds_scheduled\n",
      "    raise processed_exception\n",
      "  File \"D:\\Anaconda3\\envs\\py39\\lib\\site-packages\\autogluon\\core\\models\\ensemble\\fold_fitting_strategy.py\", line 423, in after_all_folds_scheduled\n",
      "    time_end_fit, predict_time, predict_1_time = self.ray.get(finished)\n",
      "  File \"D:\\Anaconda3\\envs\\py39\\lib\\site-packages\\ray\\_private\\client_mode_hook.py\", line 89, in wrapper\n",
      "    return func(*args, **kwargs)\n",
      "  File \"D:\\Anaconda3\\envs\\py39\\lib\\site-packages\\ray\\worker.py\", line 1621, in get\n",
      "    raise value.as_instanceof_cause()\n",
      "ray.exceptions.RayTaskError(OSError): \u001b[36mray::_ray_fit()\u001b[39m (pid=40888, ip=192.168.1.5)\n",
      "  File \"python\\ray\\_raylet.pyx\", line 568, in ray._raylet.execute_task\n",
      "  File \"python\\ray\\_raylet.pyx\", line 572, in ray._raylet.execute_task\n",
      "  File \"D:\\Anaconda3\\envs\\py39\\lib\\site-packages\\autogluon\\core\\models\\ensemble\\fold_fitting_strategy.py\", line 288, in _ray_fit\n",
      "    fold_model.fit(X=X_fold, y=y_fold, X_val=X_val_fold, y_val=y_val_fold,\n",
      "  File \"D:\\Anaconda3\\envs\\py39\\lib\\site-packages\\autogluon\\core\\models\\abstract\\abstract_model.py\", line 577, in fit\n",
      "    out = self._fit(**kwargs)\n",
      "  File \"D:\\Anaconda3\\envs\\py39\\lib\\site-packages\\autogluon\\tabular\\models\\fastainn\\tabular_nn_fastai.py\", line 169, in _fit\n",
      "    try_import_fastai()\n",
      "  File \"D:\\Anaconda3\\envs\\py39\\lib\\site-packages\\autogluon\\core\\utils\\try_import.py\", line 128, in try_import_fastai\n",
      "    import autogluon.tabular.models.fastainn.imports_helper\n",
      "  File \"D:\\Anaconda3\\envs\\py39\\lib\\site-packages\\autogluon\\tabular\\models\\fastainn\\imports_helper.py\", line 1, in <module>\n",
      "    from fastai.tabular.all import *\n",
      "  File \"D:\\Anaconda3\\envs\\py39\\lib\\site-packages\\fastai\\tabular\\all.py\", line 1, in <module>\n",
      "    from ..basics import *\n",
      "  File \"D:\\Anaconda3\\envs\\py39\\lib\\site-packages\\fastai\\basics.py\", line 1, in <module>\n",
      "    from .data.all import *\n",
      "  File \"D:\\Anaconda3\\envs\\py39\\lib\\site-packages\\fastai\\data\\all.py\", line 1, in <module>\n",
      "    from ..torch_basics import *\n",
      "  File \"D:\\Anaconda3\\envs\\py39\\lib\\site-packages\\fastai\\torch_basics.py\", line 1, in <module>\n",
      "    from torch import multiprocessing\n",
      "  File \"D:\\Anaconda3\\envs\\py39\\lib\\site-packages\\torch\\__init__.py\", line 124, in <module>\n",
      "    raise err\n",
      "OSError: [WinError 1455] 页面文件太小，无法完成操作。 Error loading \"D:\\Anaconda3\\envs\\py39\\lib\\site-packages\\torch\\lib\\cudnn_cnn_infer64_8.dll\" or one of its dependencies.\n",
      "Fitting model: LightGBMXT_BAG_L2 ...\n",
      "\tFitting 8 child models (S1F1 - S1F8) | Fitting with ParallelLocalFoldFittingStrategy\n",
      "\tWarning: Exception caused LightGBMXT_BAG_L2 to fail during training... Skipping this model.\n",
      "\t\t\u001b[36mray::_ray_fit()\u001b[39m (pid=17204, ip=192.168.1.5)\n",
      "  File \"python\\ray\\_raylet.pyx\", line 568, in ray._raylet.execute_task\n",
      "  File \"python\\ray\\_raylet.pyx\", line 572, in ray._raylet.execute_task\n",
      "  File \"D:\\Anaconda3\\envs\\py39\\lib\\site-packages\\autogluon\\core\\models\\ensemble\\fold_fitting_strategy.py\", line 294, in _ray_fit\n",
      "    fold_model.save()\n",
      "  File \"D:\\Anaconda3\\envs\\py39\\lib\\site-packages\\autogluon\\core\\models\\abstract\\abstract_model.py\", line 764, in save\n",
      "    save_pkl.save(path=file_path, object=self, verbose=verbose)\n",
      "  File \"D:\\Anaconda3\\envs\\py39\\lib\\site-packages\\autogluon\\common\\savers\\save_pkl.py\", line 21, in save\n",
      "    save_with_fn(validated_path, object, pickle_fn, format=format, verbose=verbose, compression_fn=compression_fn,\n",
      "  File \"D:\\Anaconda3\\envs\\py39\\lib\\site-packages\\autogluon\\common\\savers\\save_pkl.py\", line 38, in save_with_fn\n",
      "    pickle_fn(object, fout)\n",
      "  File \"D:\\Anaconda3\\envs\\py39\\lib\\site-packages\\autogluon\\common\\savers\\save_pkl.py\", line 20, in <lambda>\n",
      "    pickle_fn = lambda o, buffer: pickle.dump(o, buffer, protocol=4)\n",
      "_pickle.PicklingError: Can't pickle <function macro_f1 at 0x000001BFF902FCA0>: attribute lookup macro_f1 on __main__ failed\n",
      "Detailed Traceback:\n",
      "Traceback (most recent call last):\n",
      "  File \"D:\\Anaconda3\\envs\\py39\\lib\\site-packages\\autogluon\\core\\trainer\\abstract_trainer.py\", line 1074, in _train_and_save\n",
      "    model = self._train_single(X, y, model, X_val, y_val, **model_fit_kwargs)\n",
      "  File \"D:\\Anaconda3\\envs\\py39\\lib\\site-packages\\autogluon\\core\\trainer\\abstract_trainer.py\", line 1032, in _train_single\n",
      "    model = model.fit(X=X, y=y, X_val=X_val, y_val=y_val, **model_fit_kwargs)\n",
      "  File \"D:\\Anaconda3\\envs\\py39\\lib\\site-packages\\autogluon\\core\\models\\abstract\\abstract_model.py\", line 577, in fit\n",
      "    out = self._fit(**kwargs)\n",
      "  File \"D:\\Anaconda3\\envs\\py39\\lib\\site-packages\\autogluon\\core\\models\\ensemble\\stacker_ensemble_model.py\", line 153, in _fit\n",
      "    return super()._fit(X=X, y=y, time_limit=time_limit, **kwargs)\n",
      "  File \"D:\\Anaconda3\\envs\\py39\\lib\\site-packages\\autogluon\\core\\models\\ensemble\\bagged_ensemble_model.py\", line 211, in _fit\n",
      "    self._fit_folds(X=X, y=y, model_base=model_base, X_pseudo=X_pseudo, y_pseudo=y_pseudo,\n",
      "  File \"D:\\Anaconda3\\envs\\py39\\lib\\site-packages\\autogluon\\core\\models\\ensemble\\bagged_ensemble_model.py\", line 481, in _fit_folds\n",
      "    fold_fitting_strategy.after_all_folds_scheduled()\n",
      "  File \"D:\\Anaconda3\\envs\\py39\\lib\\site-packages\\autogluon\\core\\models\\ensemble\\fold_fitting_strategy.py\", line 455, in after_all_folds_scheduled\n",
      "    raise processed_exception\n",
      "  File \"D:\\Anaconda3\\envs\\py39\\lib\\site-packages\\autogluon\\core\\models\\ensemble\\fold_fitting_strategy.py\", line 423, in after_all_folds_scheduled\n",
      "    time_end_fit, predict_time, predict_1_time = self.ray.get(finished)\n",
      "  File \"D:\\Anaconda3\\envs\\py39\\lib\\site-packages\\ray\\_private\\client_mode_hook.py\", line 89, in wrapper\n",
      "    return func(*args, **kwargs)\n",
      "  File \"D:\\Anaconda3\\envs\\py39\\lib\\site-packages\\ray\\worker.py\", line 1621, in get\n",
      "    raise value.as_instanceof_cause()\n",
      "ray.exceptions.RayTaskError(PicklingError): \u001b[36mray::_ray_fit()\u001b[39m (pid=17204, ip=192.168.1.5)\n",
      "  File \"python\\ray\\_raylet.pyx\", line 568, in ray._raylet.execute_task\n",
      "  File \"python\\ray\\_raylet.pyx\", line 572, in ray._raylet.execute_task\n",
      "  File \"D:\\Anaconda3\\envs\\py39\\lib\\site-packages\\autogluon\\core\\models\\ensemble\\fold_fitting_strategy.py\", line 294, in _ray_fit\n",
      "    fold_model.save()\n",
      "  File \"D:\\Anaconda3\\envs\\py39\\lib\\site-packages\\autogluon\\core\\models\\abstract\\abstract_model.py\", line 764, in save\n",
      "    save_pkl.save(path=file_path, object=self, verbose=verbose)\n",
      "  File \"D:\\Anaconda3\\envs\\py39\\lib\\site-packages\\autogluon\\common\\savers\\save_pkl.py\", line 21, in save\n",
      "    save_with_fn(validated_path, object, pickle_fn, format=format, verbose=verbose, compression_fn=compression_fn,\n",
      "  File \"D:\\Anaconda3\\envs\\py39\\lib\\site-packages\\autogluon\\common\\savers\\save_pkl.py\", line 38, in save_with_fn\n",
      "    pickle_fn(object, fout)\n",
      "  File \"D:\\Anaconda3\\envs\\py39\\lib\\site-packages\\autogluon\\common\\savers\\save_pkl.py\", line 20, in <lambda>\n",
      "    pickle_fn = lambda o, buffer: pickle.dump(o, buffer, protocol=4)\n",
      "_pickle.PicklingError: Can't pickle <function macro_f1 at 0x000001BFF902FCA0>: attribute lookup macro_f1 on __main__ failed\n"
     ]
    },
    {
     "name": "stderr",
     "output_type": "stream",
     "text": [
      "Fitting model: LightGBM_BAG_L2 ...\n",
      "\tFitting 8 child models (S1F1 - S1F8) | Fitting with ParallelLocalFoldFittingStrategy\n",
      "\tWarning: Exception caused LightGBM_BAG_L2 to fail during training... Skipping this model.\n",
      "\t\t\u001b[36mray::_ray_fit()\u001b[39m (pid=43092, ip=192.168.1.5)\n",
      "  File \"python\\ray\\_raylet.pyx\", line 568, in ray._raylet.execute_task\n",
      "  File \"python\\ray\\_raylet.pyx\", line 572, in ray._raylet.execute_task\n",
      "  File \"D:\\Anaconda3\\envs\\py39\\lib\\site-packages\\autogluon\\core\\models\\ensemble\\fold_fitting_strategy.py\", line 294, in _ray_fit\n",
      "    fold_model.save()\n",
      "  File \"D:\\Anaconda3\\envs\\py39\\lib\\site-packages\\autogluon\\core\\models\\abstract\\abstract_model.py\", line 764, in save\n",
      "    save_pkl.save(path=file_path, object=self, verbose=verbose)\n",
      "  File \"D:\\Anaconda3\\envs\\py39\\lib\\site-packages\\autogluon\\common\\savers\\save_pkl.py\", line 21, in save\n",
      "    save_with_fn(validated_path, object, pickle_fn, format=format, verbose=verbose, compression_fn=compression_fn,\n",
      "  File \"D:\\Anaconda3\\envs\\py39\\lib\\site-packages\\autogluon\\common\\savers\\save_pkl.py\", line 38, in save_with_fn\n",
      "    pickle_fn(object, fout)\n",
      "  File \"D:\\Anaconda3\\envs\\py39\\lib\\site-packages\\autogluon\\common\\savers\\save_pkl.py\", line 20, in <lambda>\n",
      "    pickle_fn = lambda o, buffer: pickle.dump(o, buffer, protocol=4)\n",
      "_pickle.PicklingError: Can't pickle <function macro_f1 at 0x0000016B81FEFCA0>: attribute lookup macro_f1 on __main__ failed\n",
      "Detailed Traceback:\n",
      "Traceback (most recent call last):\n",
      "  File \"D:\\Anaconda3\\envs\\py39\\lib\\site-packages\\autogluon\\core\\trainer\\abstract_trainer.py\", line 1074, in _train_and_save\n",
      "    model = self._train_single(X, y, model, X_val, y_val, **model_fit_kwargs)\n",
      "  File \"D:\\Anaconda3\\envs\\py39\\lib\\site-packages\\autogluon\\core\\trainer\\abstract_trainer.py\", line 1032, in _train_single\n",
      "    model = model.fit(X=X, y=y, X_val=X_val, y_val=y_val, **model_fit_kwargs)\n",
      "  File \"D:\\Anaconda3\\envs\\py39\\lib\\site-packages\\autogluon\\core\\models\\abstract\\abstract_model.py\", line 577, in fit\n",
      "    out = self._fit(**kwargs)\n",
      "  File \"D:\\Anaconda3\\envs\\py39\\lib\\site-packages\\autogluon\\core\\models\\ensemble\\stacker_ensemble_model.py\", line 153, in _fit\n",
      "    return super()._fit(X=X, y=y, time_limit=time_limit, **kwargs)\n",
      "  File \"D:\\Anaconda3\\envs\\py39\\lib\\site-packages\\autogluon\\core\\models\\ensemble\\bagged_ensemble_model.py\", line 211, in _fit\n",
      "    self._fit_folds(X=X, y=y, model_base=model_base, X_pseudo=X_pseudo, y_pseudo=y_pseudo,\n",
      "  File \"D:\\Anaconda3\\envs\\py39\\lib\\site-packages\\autogluon\\core\\models\\ensemble\\bagged_ensemble_model.py\", line 481, in _fit_folds\n",
      "    fold_fitting_strategy.after_all_folds_scheduled()\n",
      "  File \"D:\\Anaconda3\\envs\\py39\\lib\\site-packages\\autogluon\\core\\models\\ensemble\\fold_fitting_strategy.py\", line 455, in after_all_folds_scheduled\n",
      "    raise processed_exception\n",
      "  File \"D:\\Anaconda3\\envs\\py39\\lib\\site-packages\\autogluon\\core\\models\\ensemble\\fold_fitting_strategy.py\", line 423, in after_all_folds_scheduled\n",
      "    time_end_fit, predict_time, predict_1_time = self.ray.get(finished)\n",
      "  File \"D:\\Anaconda3\\envs\\py39\\lib\\site-packages\\ray\\_private\\client_mode_hook.py\", line 89, in wrapper\n",
      "    return func(*args, **kwargs)\n",
      "  File \"D:\\Anaconda3\\envs\\py39\\lib\\site-packages\\ray\\worker.py\", line 1621, in get\n",
      "    raise value.as_instanceof_cause()\n",
      "ray.exceptions.RayTaskError(PicklingError): \u001b[36mray::_ray_fit()\u001b[39m (pid=43092, ip=192.168.1.5)\n",
      "  File \"python\\ray\\_raylet.pyx\", line 568, in ray._raylet.execute_task\n",
      "  File \"python\\ray\\_raylet.pyx\", line 572, in ray._raylet.execute_task\n",
      "  File \"D:\\Anaconda3\\envs\\py39\\lib\\site-packages\\autogluon\\core\\models\\ensemble\\fold_fitting_strategy.py\", line 294, in _ray_fit\n",
      "    fold_model.save()\n",
      "  File \"D:\\Anaconda3\\envs\\py39\\lib\\site-packages\\autogluon\\core\\models\\abstract\\abstract_model.py\", line 764, in save\n",
      "    save_pkl.save(path=file_path, object=self, verbose=verbose)\n",
      "  File \"D:\\Anaconda3\\envs\\py39\\lib\\site-packages\\autogluon\\common\\savers\\save_pkl.py\", line 21, in save\n",
      "    save_with_fn(validated_path, object, pickle_fn, format=format, verbose=verbose, compression_fn=compression_fn,\n",
      "  File \"D:\\Anaconda3\\envs\\py39\\lib\\site-packages\\autogluon\\common\\savers\\save_pkl.py\", line 38, in save_with_fn\n",
      "    pickle_fn(object, fout)\n",
      "  File \"D:\\Anaconda3\\envs\\py39\\lib\\site-packages\\autogluon\\common\\savers\\save_pkl.py\", line 20, in <lambda>\n",
      "    pickle_fn = lambda o, buffer: pickle.dump(o, buffer, protocol=4)\n",
      "_pickle.PicklingError: Can't pickle <function macro_f1 at 0x0000016B81FEFCA0>: attribute lookup macro_f1 on __main__ failed\n",
      "Fitting model: RandomForestGini_BAG_L2 ...\n",
      "\t0.7988\t = Validation score   (macro_f1)\n",
      "\t2.88s\t = Training   runtime\n",
      "\t6.4s\t = Validation runtime\n",
      "Fitting model: RandomForestEntr_BAG_L2 ...\n",
      "\t0.8019\t = Validation score   (macro_f1)\n",
      "\t2.61s\t = Training   runtime\n",
      "\t6.38s\t = Validation runtime\n",
      "Fitting model: CatBoost_BAG_L2 ...\n",
      "\tFitting 8 child models (S1F1 - S1F8) | Fitting with ParallelLocalFoldFittingStrategy\n",
      "\tWarning: Exception caused CatBoost_BAG_L2 to fail during training... Skipping this model.\n",
      "\t\t\u001b[36mray::_ray_fit()\u001b[39m (pid=23432, ip=192.168.1.5)\n",
      "  File \"python\\ray\\_raylet.pyx\", line 568, in ray._raylet.execute_task\n",
      "  File \"python\\ray\\_raylet.pyx\", line 572, in ray._raylet.execute_task\n",
      "  File \"D:\\Anaconda3\\envs\\py39\\lib\\site-packages\\autogluon\\core\\models\\ensemble\\fold_fitting_strategy.py\", line 294, in _ray_fit\n",
      "    fold_model.save()\n",
      "  File \"D:\\Anaconda3\\envs\\py39\\lib\\site-packages\\autogluon\\core\\models\\abstract\\abstract_model.py\", line 764, in save\n",
      "    save_pkl.save(path=file_path, object=self, verbose=verbose)\n",
      "  File \"D:\\Anaconda3\\envs\\py39\\lib\\site-packages\\autogluon\\common\\savers\\save_pkl.py\", line 21, in save\n",
      "    save_with_fn(validated_path, object, pickle_fn, format=format, verbose=verbose, compression_fn=compression_fn,\n",
      "  File \"D:\\Anaconda3\\envs\\py39\\lib\\site-packages\\autogluon\\common\\savers\\save_pkl.py\", line 38, in save_with_fn\n",
      "    pickle_fn(object, fout)\n",
      "  File \"D:\\Anaconda3\\envs\\py39\\lib\\site-packages\\autogluon\\common\\savers\\save_pkl.py\", line 20, in <lambda>\n",
      "    pickle_fn = lambda o, buffer: pickle.dump(o, buffer, protocol=4)\n",
      "_pickle.PicklingError: Can't pickle <function macro_f1 at 0x000002E93F34FCA0>: attribute lookup macro_f1 on __main__ failed\n",
      "Detailed Traceback:\n",
      "Traceback (most recent call last):\n",
      "  File \"D:\\Anaconda3\\envs\\py39\\lib\\site-packages\\autogluon\\core\\trainer\\abstract_trainer.py\", line 1074, in _train_and_save\n",
      "    model = self._train_single(X, y, model, X_val, y_val, **model_fit_kwargs)\n",
      "  File \"D:\\Anaconda3\\envs\\py39\\lib\\site-packages\\autogluon\\core\\trainer\\abstract_trainer.py\", line 1032, in _train_single\n",
      "    model = model.fit(X=X, y=y, X_val=X_val, y_val=y_val, **model_fit_kwargs)\n",
      "  File \"D:\\Anaconda3\\envs\\py39\\lib\\site-packages\\autogluon\\core\\models\\abstract\\abstract_model.py\", line 577, in fit\n",
      "    out = self._fit(**kwargs)\n",
      "  File \"D:\\Anaconda3\\envs\\py39\\lib\\site-packages\\autogluon\\core\\models\\ensemble\\stacker_ensemble_model.py\", line 153, in _fit\n",
      "    return super()._fit(X=X, y=y, time_limit=time_limit, **kwargs)\n",
      "  File \"D:\\Anaconda3\\envs\\py39\\lib\\site-packages\\autogluon\\core\\models\\ensemble\\bagged_ensemble_model.py\", line 211, in _fit\n",
      "    self._fit_folds(X=X, y=y, model_base=model_base, X_pseudo=X_pseudo, y_pseudo=y_pseudo,\n",
      "  File \"D:\\Anaconda3\\envs\\py39\\lib\\site-packages\\autogluon\\core\\models\\ensemble\\bagged_ensemble_model.py\", line 481, in _fit_folds\n",
      "    fold_fitting_strategy.after_all_folds_scheduled()\n",
      "  File \"D:\\Anaconda3\\envs\\py39\\lib\\site-packages\\autogluon\\core\\models\\ensemble\\fold_fitting_strategy.py\", line 455, in after_all_folds_scheduled\n",
      "    raise processed_exception\n",
      "  File \"D:\\Anaconda3\\envs\\py39\\lib\\site-packages\\autogluon\\core\\models\\ensemble\\fold_fitting_strategy.py\", line 423, in after_all_folds_scheduled\n",
      "    time_end_fit, predict_time, predict_1_time = self.ray.get(finished)\n",
      "  File \"D:\\Anaconda3\\envs\\py39\\lib\\site-packages\\ray\\_private\\client_mode_hook.py\", line 89, in wrapper\n",
      "    return func(*args, **kwargs)\n",
      "  File \"D:\\Anaconda3\\envs\\py39\\lib\\site-packages\\ray\\worker.py\", line 1621, in get\n",
      "    raise value.as_instanceof_cause()\n",
      "ray.exceptions.RayTaskError(PicklingError): \u001b[36mray::_ray_fit()\u001b[39m (pid=23432, ip=192.168.1.5)\n",
      "  File \"python\\ray\\_raylet.pyx\", line 568, in ray._raylet.execute_task\n",
      "  File \"python\\ray\\_raylet.pyx\", line 572, in ray._raylet.execute_task\n",
      "  File \"D:\\Anaconda3\\envs\\py39\\lib\\site-packages\\autogluon\\core\\models\\ensemble\\fold_fitting_strategy.py\", line 294, in _ray_fit\n",
      "    fold_model.save()\n",
      "  File \"D:\\Anaconda3\\envs\\py39\\lib\\site-packages\\autogluon\\core\\models\\abstract\\abstract_model.py\", line 764, in save\n",
      "    save_pkl.save(path=file_path, object=self, verbose=verbose)\n",
      "  File \"D:\\Anaconda3\\envs\\py39\\lib\\site-packages\\autogluon\\common\\savers\\save_pkl.py\", line 21, in save\n",
      "    save_with_fn(validated_path, object, pickle_fn, format=format, verbose=verbose, compression_fn=compression_fn,\n",
      "  File \"D:\\Anaconda3\\envs\\py39\\lib\\site-packages\\autogluon\\common\\savers\\save_pkl.py\", line 38, in save_with_fn\n",
      "    pickle_fn(object, fout)\n",
      "  File \"D:\\Anaconda3\\envs\\py39\\lib\\site-packages\\autogluon\\common\\savers\\save_pkl.py\", line 20, in <lambda>\n",
      "    pickle_fn = lambda o, buffer: pickle.dump(o, buffer, protocol=4)\n",
      "_pickle.PicklingError: Can't pickle <function macro_f1 at 0x000002E93F34FCA0>: attribute lookup macro_f1 on __main__ failed\n"
     ]
    },
    {
     "name": "stderr",
     "output_type": "stream",
     "text": [
      "Fitting model: ExtraTreesGini_BAG_L2 ...\n",
      "\t0.7963\t = Validation score   (macro_f1)\n",
      "\t3.48s\t = Training   runtime\n",
      "\t6.45s\t = Validation runtime\n",
      "Fitting model: ExtraTreesEntr_BAG_L2 ...\n",
      "\t0.7978\t = Validation score   (macro_f1)\n",
      "\t3.4s\t = Training   runtime\n",
      "\t6.57s\t = Validation runtime\n",
      "Fitting model: XGBoost_BAG_L2 ...\n",
      "\tFitting 8 child models (S1F1 - S1F8) | Fitting with ParallelLocalFoldFittingStrategy\n",
      "\tWarning: Exception caused XGBoost_BAG_L2 to fail during training... Skipping this model.\n",
      "\t\t\u001b[36mray::_ray_fit()\u001b[39m (pid=34568, ip=192.168.1.5)\n",
      "  File \"python\\ray\\_raylet.pyx\", line 568, in ray._raylet.execute_task\n",
      "  File \"python\\ray\\_raylet.pyx\", line 572, in ray._raylet.execute_task\n",
      "  File \"D:\\Anaconda3\\envs\\py39\\lib\\site-packages\\autogluon\\core\\models\\ensemble\\fold_fitting_strategy.py\", line 294, in _ray_fit\n",
      "    fold_model.save()\n",
      "  File \"D:\\Anaconda3\\envs\\py39\\lib\\site-packages\\autogluon\\tabular\\models\\xgboost\\xgboost_model.py\", line 209, in save\n",
      "    path = super().save(path=path, verbose=verbose)\n",
      "  File \"D:\\Anaconda3\\envs\\py39\\lib\\site-packages\\autogluon\\core\\models\\abstract\\abstract_model.py\", line 764, in save\n",
      "    save_pkl.save(path=file_path, object=self, verbose=verbose)\n",
      "  File \"D:\\Anaconda3\\envs\\py39\\lib\\site-packages\\autogluon\\common\\savers\\save_pkl.py\", line 21, in save\n",
      "    save_with_fn(validated_path, object, pickle_fn, format=format, verbose=verbose, compression_fn=compression_fn,\n",
      "  File \"D:\\Anaconda3\\envs\\py39\\lib\\site-packages\\autogluon\\common\\savers\\save_pkl.py\", line 38, in save_with_fn\n",
      "    pickle_fn(object, fout)\n",
      "  File \"D:\\Anaconda3\\envs\\py39\\lib\\site-packages\\autogluon\\common\\savers\\save_pkl.py\", line 20, in <lambda>\n",
      "    pickle_fn = lambda o, buffer: pickle.dump(o, buffer, protocol=4)\n",
      "_pickle.PicklingError: Can't pickle <function macro_f1 at 0x000001C43A0AFCA0>: attribute lookup macro_f1 on __main__ failed\n",
      "Detailed Traceback:\n",
      "Traceback (most recent call last):\n",
      "  File \"D:\\Anaconda3\\envs\\py39\\lib\\site-packages\\autogluon\\core\\trainer\\abstract_trainer.py\", line 1074, in _train_and_save\n",
      "    model = self._train_single(X, y, model, X_val, y_val, **model_fit_kwargs)\n",
      "  File \"D:\\Anaconda3\\envs\\py39\\lib\\site-packages\\autogluon\\core\\trainer\\abstract_trainer.py\", line 1032, in _train_single\n",
      "    model = model.fit(X=X, y=y, X_val=X_val, y_val=y_val, **model_fit_kwargs)\n",
      "  File \"D:\\Anaconda3\\envs\\py39\\lib\\site-packages\\autogluon\\core\\models\\abstract\\abstract_model.py\", line 577, in fit\n",
      "    out = self._fit(**kwargs)\n",
      "  File \"D:\\Anaconda3\\envs\\py39\\lib\\site-packages\\autogluon\\core\\models\\ensemble\\stacker_ensemble_model.py\", line 153, in _fit\n",
      "    return super()._fit(X=X, y=y, time_limit=time_limit, **kwargs)\n",
      "  File \"D:\\Anaconda3\\envs\\py39\\lib\\site-packages\\autogluon\\core\\models\\ensemble\\bagged_ensemble_model.py\", line 211, in _fit\n",
      "    self._fit_folds(X=X, y=y, model_base=model_base, X_pseudo=X_pseudo, y_pseudo=y_pseudo,\n",
      "  File \"D:\\Anaconda3\\envs\\py39\\lib\\site-packages\\autogluon\\core\\models\\ensemble\\bagged_ensemble_model.py\", line 481, in _fit_folds\n",
      "    fold_fitting_strategy.after_all_folds_scheduled()\n",
      "  File \"D:\\Anaconda3\\envs\\py39\\lib\\site-packages\\autogluon\\core\\models\\ensemble\\fold_fitting_strategy.py\", line 455, in after_all_folds_scheduled\n",
      "    raise processed_exception\n",
      "  File \"D:\\Anaconda3\\envs\\py39\\lib\\site-packages\\autogluon\\core\\models\\ensemble\\fold_fitting_strategy.py\", line 423, in after_all_folds_scheduled\n",
      "    time_end_fit, predict_time, predict_1_time = self.ray.get(finished)\n",
      "  File \"D:\\Anaconda3\\envs\\py39\\lib\\site-packages\\ray\\_private\\client_mode_hook.py\", line 89, in wrapper\n",
      "    return func(*args, **kwargs)\n",
      "  File \"D:\\Anaconda3\\envs\\py39\\lib\\site-packages\\ray\\worker.py\", line 1621, in get\n",
      "    raise value.as_instanceof_cause()\n",
      "ray.exceptions.RayTaskError(PicklingError): \u001b[36mray::_ray_fit()\u001b[39m (pid=34568, ip=192.168.1.5)\n",
      "  File \"python\\ray\\_raylet.pyx\", line 568, in ray._raylet.execute_task\n",
      "  File \"python\\ray\\_raylet.pyx\", line 572, in ray._raylet.execute_task\n",
      "  File \"D:\\Anaconda3\\envs\\py39\\lib\\site-packages\\autogluon\\core\\models\\ensemble\\fold_fitting_strategy.py\", line 294, in _ray_fit\n",
      "    fold_model.save()\n",
      "  File \"D:\\Anaconda3\\envs\\py39\\lib\\site-packages\\autogluon\\tabular\\models\\xgboost\\xgboost_model.py\", line 209, in save\n",
      "    path = super().save(path=path, verbose=verbose)\n",
      "  File \"D:\\Anaconda3\\envs\\py39\\lib\\site-packages\\autogluon\\core\\models\\abstract\\abstract_model.py\", line 764, in save\n",
      "    save_pkl.save(path=file_path, object=self, verbose=verbose)\n",
      "  File \"D:\\Anaconda3\\envs\\py39\\lib\\site-packages\\autogluon\\common\\savers\\save_pkl.py\", line 21, in save\n",
      "    save_with_fn(validated_path, object, pickle_fn, format=format, verbose=verbose, compression_fn=compression_fn,\n",
      "  File \"D:\\Anaconda3\\envs\\py39\\lib\\site-packages\\autogluon\\common\\savers\\save_pkl.py\", line 38, in save_with_fn\n",
      "    pickle_fn(object, fout)\n",
      "  File \"D:\\Anaconda3\\envs\\py39\\lib\\site-packages\\autogluon\\common\\savers\\save_pkl.py\", line 20, in <lambda>\n",
      "    pickle_fn = lambda o, buffer: pickle.dump(o, buffer, protocol=4)\n",
      "_pickle.PicklingError: Can't pickle <function macro_f1 at 0x000001C43A0AFCA0>: attribute lookup macro_f1 on __main__ failed\n",
      "Fitting model: NeuralNetTorch_BAG_L2 ...\n",
      "\tFitting 8 child models (S1F1 - S1F8) | Fitting with ParallelLocalFoldFittingStrategy\n",
      "\tWarning: Exception caused NeuralNetTorch_BAG_L2 to fail during training... Skipping this model.\n",
      "\t\t\u001b[36mray::_ray_fit()\u001b[39m (pid=40684, ip=192.168.1.5)\n",
      "  File \"python\\ray\\_raylet.pyx\", line 568, in ray._raylet.execute_task\n",
      "  File \"python\\ray\\_raylet.pyx\", line 572, in ray._raylet.execute_task\n",
      "  File \"D:\\Anaconda3\\envs\\py39\\lib\\site-packages\\autogluon\\core\\models\\ensemble\\fold_fitting_strategy.py\", line 288, in _ray_fit\n",
      "    fold_model.fit(X=X_fold, y=y_fold, X_val=X_val_fold, y_val=y_val_fold,\n",
      "  File \"D:\\Anaconda3\\envs\\py39\\lib\\site-packages\\autogluon\\core\\models\\abstract\\abstract_model.py\", line 577, in fit\n",
      "    out = self._fit(**kwargs)\n",
      "  File \"D:\\Anaconda3\\envs\\py39\\lib\\site-packages\\autogluon\\tabular\\models\\tabular_nn\\torch\\tabular_nn_torch.py\", line 196, in _fit\n",
      "    self._train_net(train_dataset=train_dataset,\n",
      "  File \"D:\\Anaconda3\\envs\\py39\\lib\\site-packages\\autogluon\\tabular\\models\\tabular_nn\\torch\\tabular_nn_torch.py\", line 293, in _train_net\n",
      "    loss = self.model.compute_loss(data_batch, **loss_kwargs)\n",
      "  File \"D:\\Anaconda3\\envs\\py39\\lib\\site-packages\\autogluon\\tabular\\models\\tabular_nn\\torch\\torch_network_modules.py\", line 229, in compute_loss\n",
      "    predict_data = self(data_batch)\n",
      "  File \"D:\\Anaconda3\\envs\\py39\\lib\\site-packages\\torch\\nn\\modules\\module.py\", line 1102, in _call_impl\n",
      "    return forward_call(*input, **kwargs)\n",
      "  File \"D:\\Anaconda3\\envs\\py39\\lib\\site-packages\\autogluon\\tabular\\models\\tabular_nn\\torch\\torch_network_modules.py\", line 169, in forward\n",
      "    output_data = self.main_block(input_data)\n",
      "  File \"D:\\Anaconda3\\envs\\py39\\lib\\site-packages\\torch\\nn\\modules\\module.py\", line 1102, in _call_impl\n",
      "    return forward_call(*input, **kwargs)\n",
      "  File \"D:\\Anaconda3\\envs\\py39\\lib\\site-packages\\torch\\nn\\modules\\container.py\", line 141, in forward\n",
      "    input = module(input)\n",
      "  File \"D:\\Anaconda3\\envs\\py39\\lib\\site-packages\\torch\\nn\\modules\\module.py\", line 1102, in _call_impl\n",
      "    return forward_call(*input, **kwargs)\n",
      "  File \"D:\\Anaconda3\\envs\\py39\\lib\\site-packages\\torch\\nn\\modules\\dropout.py\", line 58, in forward\n",
      "    return F.dropout(input, self.p, self.training, self.inplace)\n",
      "  File \"D:\\Anaconda3\\envs\\py39\\lib\\site-packages\\torch\\nn\\functional.py\", line 1169, in dropout\n",
      "    return _VF.dropout_(input, p, training) if inplace else _VF.dropout(input, p, training)\n",
      "RuntimeError: [enforce fail at ..\\c10\\core\\CPUAllocator.cpp:76] data. DefaultCPUAllocator: not enough memory: you tried to allocate 65536 bytes.\n",
      "Detailed Traceback:\n",
      "Traceback (most recent call last):\n",
      "  File \"D:\\Anaconda3\\envs\\py39\\lib\\site-packages\\autogluon\\core\\trainer\\abstract_trainer.py\", line 1074, in _train_and_save\n",
      "    model = self._train_single(X, y, model, X_val, y_val, **model_fit_kwargs)\n",
      "  File \"D:\\Anaconda3\\envs\\py39\\lib\\site-packages\\autogluon\\core\\trainer\\abstract_trainer.py\", line 1032, in _train_single\n",
      "    model = model.fit(X=X, y=y, X_val=X_val, y_val=y_val, **model_fit_kwargs)\n",
      "  File \"D:\\Anaconda3\\envs\\py39\\lib\\site-packages\\autogluon\\core\\models\\abstract\\abstract_model.py\", line 577, in fit\n",
      "    out = self._fit(**kwargs)\n",
      "  File \"D:\\Anaconda3\\envs\\py39\\lib\\site-packages\\autogluon\\core\\models\\ensemble\\stacker_ensemble_model.py\", line 153, in _fit\n",
      "    return super()._fit(X=X, y=y, time_limit=time_limit, **kwargs)\n",
      "  File \"D:\\Anaconda3\\envs\\py39\\lib\\site-packages\\autogluon\\core\\models\\ensemble\\bagged_ensemble_model.py\", line 211, in _fit\n",
      "    self._fit_folds(X=X, y=y, model_base=model_base, X_pseudo=X_pseudo, y_pseudo=y_pseudo,\n",
      "  File \"D:\\Anaconda3\\envs\\py39\\lib\\site-packages\\autogluon\\core\\models\\ensemble\\bagged_ensemble_model.py\", line 481, in _fit_folds\n",
      "    fold_fitting_strategy.after_all_folds_scheduled()\n",
      "  File \"D:\\Anaconda3\\envs\\py39\\lib\\site-packages\\autogluon\\core\\models\\ensemble\\fold_fitting_strategy.py\", line 455, in after_all_folds_scheduled\n",
      "    raise processed_exception\n",
      "  File \"D:\\Anaconda3\\envs\\py39\\lib\\site-packages\\autogluon\\core\\models\\ensemble\\fold_fitting_strategy.py\", line 423, in after_all_folds_scheduled\n",
      "    time_end_fit, predict_time, predict_1_time = self.ray.get(finished)\n",
      "  File \"D:\\Anaconda3\\envs\\py39\\lib\\site-packages\\ray\\_private\\client_mode_hook.py\", line 89, in wrapper\n",
      "    return func(*args, **kwargs)\n",
      "  File \"D:\\Anaconda3\\envs\\py39\\lib\\site-packages\\ray\\worker.py\", line 1621, in get\n",
      "    raise value.as_instanceof_cause()\n",
      "ray.exceptions.RayTaskError(RuntimeError): \u001b[36mray::_ray_fit()\u001b[39m (pid=40684, ip=192.168.1.5)\n",
      "  File \"python\\ray\\_raylet.pyx\", line 568, in ray._raylet.execute_task\n",
      "  File \"python\\ray\\_raylet.pyx\", line 572, in ray._raylet.execute_task\n",
      "  File \"D:\\Anaconda3\\envs\\py39\\lib\\site-packages\\autogluon\\core\\models\\ensemble\\fold_fitting_strategy.py\", line 288, in _ray_fit\n",
      "    fold_model.fit(X=X_fold, y=y_fold, X_val=X_val_fold, y_val=y_val_fold,\n",
      "  File \"D:\\Anaconda3\\envs\\py39\\lib\\site-packages\\autogluon\\core\\models\\abstract\\abstract_model.py\", line 577, in fit\n",
      "    out = self._fit(**kwargs)\n",
      "  File \"D:\\Anaconda3\\envs\\py39\\lib\\site-packages\\autogluon\\tabular\\models\\tabular_nn\\torch\\tabular_nn_torch.py\", line 196, in _fit\n",
      "    self._train_net(train_dataset=train_dataset,\n",
      "  File \"D:\\Anaconda3\\envs\\py39\\lib\\site-packages\\autogluon\\tabular\\models\\tabular_nn\\torch\\tabular_nn_torch.py\", line 293, in _train_net\n",
      "    loss = self.model.compute_loss(data_batch, **loss_kwargs)\n",
      "  File \"D:\\Anaconda3\\envs\\py39\\lib\\site-packages\\autogluon\\tabular\\models\\tabular_nn\\torch\\torch_network_modules.py\", line 229, in compute_loss\n",
      "    predict_data = self(data_batch)\n",
      "  File \"D:\\Anaconda3\\envs\\py39\\lib\\site-packages\\torch\\nn\\modules\\module.py\", line 1102, in _call_impl\n",
      "    return forward_call(*input, **kwargs)\n",
      "  File \"D:\\Anaconda3\\envs\\py39\\lib\\site-packages\\autogluon\\tabular\\models\\tabular_nn\\torch\\torch_network_modules.py\", line 169, in forward\n",
      "    output_data = self.main_block(input_data)\n",
      "  File \"D:\\Anaconda3\\envs\\py39\\lib\\site-packages\\torch\\nn\\modules\\module.py\", line 1102, in _call_impl\n",
      "    return forward_call(*input, **kwargs)\n",
      "  File \"D:\\Anaconda3\\envs\\py39\\lib\\site-packages\\torch\\nn\\modules\\container.py\", line 141, in forward\n",
      "    input = module(input)\n",
      "  File \"D:\\Anaconda3\\envs\\py39\\lib\\site-packages\\torch\\nn\\modules\\module.py\", line 1102, in _call_impl\n",
      "    return forward_call(*input, **kwargs)\n",
      "  File \"D:\\Anaconda3\\envs\\py39\\lib\\site-packages\\torch\\nn\\modules\\dropout.py\", line 58, in forward\n",
      "    return F.dropout(input, self.p, self.training, self.inplace)\n",
      "  File \"D:\\Anaconda3\\envs\\py39\\lib\\site-packages\\torch\\nn\\functional.py\", line 1169, in dropout\n",
      "    return _VF.dropout_(input, p, training) if inplace else _VF.dropout(input, p, training)\n",
      "RuntimeError: [enforce fail at ..\\c10\\core\\CPUAllocator.cpp:76] data. DefaultCPUAllocator: not enough memory: you tried to allocate 65536 bytes.\n"
     ]
    },
    {
     "name": "stderr",
     "output_type": "stream",
     "text": [
      "Fitting model: LightGBMLarge_BAG_L2 ...\n",
      "\tFitting 8 child models (S1F1 - S1F8) | Fitting with ParallelLocalFoldFittingStrategy\n",
      "\tWarning: Exception caused LightGBMLarge_BAG_L2 to fail during training... Skipping this model.\n",
      "\t\tThe current node has not been updated within 30 seconds, this could happen because of some of the Ray processes failed to startup.\n",
      "Detailed Traceback:\n",
      "Traceback (most recent call last):\n",
      "  File \"D:\\Anaconda3\\envs\\py39\\lib\\site-packages\\ray\\node.py\", line 263, in __init__\n",
      "    ray._private.services.wait_for_node(\n",
      "  File \"D:\\Anaconda3\\envs\\py39\\lib\\site-packages\\ray\\_private\\services.py\", line 276, in wait_for_node\n",
      "    raise TimeoutError(\"Timed out while waiting for node to startup.\")\n",
      "TimeoutError: Timed out while waiting for node to startup.\n",
      "\n",
      "During handling of the above exception, another exception occurred:\n",
      "\n",
      "Traceback (most recent call last):\n",
      "  File \"D:\\Anaconda3\\envs\\py39\\lib\\site-packages\\autogluon\\core\\trainer\\abstract_trainer.py\", line 1074, in _train_and_save\n",
      "    model = self._train_single(X, y, model, X_val, y_val, **model_fit_kwargs)\n",
      "  File \"D:\\Anaconda3\\envs\\py39\\lib\\site-packages\\autogluon\\core\\trainer\\abstract_trainer.py\", line 1032, in _train_single\n",
      "    model = model.fit(X=X, y=y, X_val=X_val, y_val=y_val, **model_fit_kwargs)\n",
      "  File \"D:\\Anaconda3\\envs\\py39\\lib\\site-packages\\autogluon\\core\\models\\abstract\\abstract_model.py\", line 577, in fit\n",
      "    out = self._fit(**kwargs)\n",
      "  File \"D:\\Anaconda3\\envs\\py39\\lib\\site-packages\\autogluon\\core\\models\\ensemble\\stacker_ensemble_model.py\", line 153, in _fit\n",
      "    return super()._fit(X=X, y=y, time_limit=time_limit, **kwargs)\n",
      "  File \"D:\\Anaconda3\\envs\\py39\\lib\\site-packages\\autogluon\\core\\models\\ensemble\\bagged_ensemble_model.py\", line 211, in _fit\n",
      "    self._fit_folds(X=X, y=y, model_base=model_base, X_pseudo=X_pseudo, y_pseudo=y_pseudo,\n",
      "  File \"D:\\Anaconda3\\envs\\py39\\lib\\site-packages\\autogluon\\core\\models\\ensemble\\bagged_ensemble_model.py\", line 480, in _fit_folds\n",
      "    fold_fitting_strategy.schedule_fold_model_fit(**fold_fit_args)\n",
      "  File \"D:\\Anaconda3\\envs\\py39\\lib\\site-packages\\autogluon\\core\\models\\ensemble\\fold_fitting_strategy.py\", line 397, in schedule_fold_model_fit\n",
      "    self.ray.init(log_to_driver=False)\n",
      "  File \"D:\\Anaconda3\\envs\\py39\\lib\\site-packages\\ray\\_private\\client_mode_hook.py\", line 89, in wrapper\n",
      "    return func(*args, **kwargs)\n",
      "  File \"D:\\Anaconda3\\envs\\py39\\lib\\site-packages\\ray\\worker.py\", line 893, in init\n",
      "    _global_node = ray.node.Node(\n",
      "  File \"D:\\Anaconda3\\envs\\py39\\lib\\site-packages\\ray\\node.py\", line 267, in __init__\n",
      "    raise Exception(\n",
      "Exception: The current node has not been updated within 30 seconds, this could happen because of some of the Ray processes failed to startup.\n",
      "Fitting model: WeightedEnsemble_L3 ...\n",
      "\t0.8019\t = Validation score   (macro_f1)\n",
      "\t4.95s\t = Training   runtime\n",
      "\t0.02s\t = Validation runtime\n",
      "AutoGluon training complete, total runtime = 1873.28s ... Best model: \"WeightedEnsemble_L3\"\n",
      "TabularPredictor saved. To load, use: predictor = TabularPredictor.load(\"AutogluonModels/ag-20220326_112328\\\")\n"
     ]
    }
   ],
   "source": [
    "predictor = TabularPredictor(label='label',eval_metric=ag_macro_f1_scorer).fit(train_data=train_data, presets='best_quality')\n"
   ]
  },
  {
   "cell_type": "code",
   "execution_count": 9,
   "id": "a0f74289",
   "metadata": {},
   "outputs": [
    {
     "name": "stderr",
     "output_type": "stream",
     "text": [
      "Loaded data from: C:\\Users\\whchi\\Downloads\\Log-diagnosis-main\\Log-diagnosis-main\\pre_contest\\dataset\\test.csv | Columns = 2 / 2 | Rows = 3297 -> 3297\n"
     ]
    },
    {
     "data": {
      "text/html": [
       "<div>\n",
       "<style scoped>\n",
       "    .dataframe tbody tr th:only-of-type {\n",
       "        vertical-align: middle;\n",
       "    }\n",
       "\n",
       "    .dataframe tbody tr th {\n",
       "        vertical-align: top;\n",
       "    }\n",
       "\n",
       "    .dataframe thead th {\n",
       "        text-align: right;\n",
       "    }\n",
       "</style>\n",
       "<table border=\"1\" class=\"dataframe\">\n",
       "  <thead>\n",
       "    <tr style=\"text-align: right;\">\n",
       "      <th></th>\n",
       "      <th>model</th>\n",
       "      <th>score_test</th>\n",
       "      <th>score_val</th>\n",
       "      <th>pred_time_test</th>\n",
       "      <th>pred_time_val</th>\n",
       "      <th>fit_time</th>\n",
       "      <th>pred_time_test_marginal</th>\n",
       "      <th>pred_time_val_marginal</th>\n",
       "      <th>fit_time_marginal</th>\n",
       "      <th>stack_level</th>\n",
       "      <th>can_infer</th>\n",
       "      <th>fit_order</th>\n",
       "    </tr>\n",
       "  </thead>\n",
       "  <tbody>\n",
       "    <tr>\n",
       "      <th>0</th>\n",
       "      <td>RandomForestEntr_BAG_L2</td>\n",
       "      <td>0.614975</td>\n",
       "      <td>0.801908</td>\n",
       "      <td>5.300791</td>\n",
       "      <td>47.884419</td>\n",
       "      <td>24.368791</td>\n",
       "      <td>0.181079</td>\n",
       "      <td>6.376185</td>\n",
       "      <td>2.610276</td>\n",
       "      <td>2</td>\n",
       "      <td>True</td>\n",
       "      <td>9</td>\n",
       "    </tr>\n",
       "    <tr>\n",
       "      <th>1</th>\n",
       "      <td>RandomForestGini_BAG_L1</td>\n",
       "      <td>0.613703</td>\n",
       "      <td>0.609850</td>\n",
       "      <td>0.221553</td>\n",
       "      <td>6.929353</td>\n",
       "      <td>5.654842</td>\n",
       "      <td>0.221553</td>\n",
       "      <td>6.929353</td>\n",
       "      <td>5.654842</td>\n",
       "      <td>1</td>\n",
       "      <td>True</td>\n",
       "      <td>3</td>\n",
       "    </tr>\n",
       "    <tr>\n",
       "      <th>2</th>\n",
       "      <td>RandomForestGini_BAG_L2</td>\n",
       "      <td>0.611673</td>\n",
       "      <td>0.798771</td>\n",
       "      <td>5.316757</td>\n",
       "      <td>47.908111</td>\n",
       "      <td>24.642530</td>\n",
       "      <td>0.197045</td>\n",
       "      <td>6.399877</td>\n",
       "      <td>2.884016</td>\n",
       "      <td>2</td>\n",
       "      <td>True</td>\n",
       "      <td>8</td>\n",
       "    </tr>\n",
       "    <tr>\n",
       "      <th>3</th>\n",
       "      <td>RandomForestEntr_BAG_L1</td>\n",
       "      <td>0.609681</td>\n",
       "      <td>0.610286</td>\n",
       "      <td>0.228779</td>\n",
       "      <td>7.152787</td>\n",
       "      <td>5.511570</td>\n",
       "      <td>0.228779</td>\n",
       "      <td>7.152787</td>\n",
       "      <td>5.511570</td>\n",
       "      <td>1</td>\n",
       "      <td>True</td>\n",
       "      <td>4</td>\n",
       "    </tr>\n",
       "    <tr>\n",
       "      <th>4</th>\n",
       "      <td>ExtraTreesGini_BAG_L2</td>\n",
       "      <td>0.608957</td>\n",
       "      <td>0.796278</td>\n",
       "      <td>5.321757</td>\n",
       "      <td>47.958304</td>\n",
       "      <td>25.241310</td>\n",
       "      <td>0.202045</td>\n",
       "      <td>6.450070</td>\n",
       "      <td>3.482795</td>\n",
       "      <td>2</td>\n",
       "      <td>True</td>\n",
       "      <td>10</td>\n",
       "    </tr>\n",
       "    <tr>\n",
       "      <th>5</th>\n",
       "      <td>WeightedEnsemble_L2</td>\n",
       "      <td>0.608403</td>\n",
       "      <td>0.613442</td>\n",
       "      <td>0.903519</td>\n",
       "      <td>27.195234</td>\n",
       "      <td>26.262874</td>\n",
       "      <td>0.008002</td>\n",
       "      <td>0.009010</td>\n",
       "      <td>5.081489</td>\n",
       "      <td>2</td>\n",
       "      <td>True</td>\n",
       "      <td>7</td>\n",
       "    </tr>\n",
       "    <tr>\n",
       "      <th>6</th>\n",
       "      <td>WeightedEnsemble_L3</td>\n",
       "      <td>0.607067</td>\n",
       "      <td>0.801874</td>\n",
       "      <td>5.707884</td>\n",
       "      <td>60.868359</td>\n",
       "      <td>35.603527</td>\n",
       "      <td>0.006001</td>\n",
       "      <td>0.015005</td>\n",
       "      <td>4.949892</td>\n",
       "      <td>3</td>\n",
       "      <td>True</td>\n",
       "      <td>12</td>\n",
       "    </tr>\n",
       "    <tr>\n",
       "      <th>7</th>\n",
       "      <td>ExtraTreesEntr_BAG_L1</td>\n",
       "      <td>0.604699</td>\n",
       "      <td>0.609835</td>\n",
       "      <td>0.226135</td>\n",
       "      <td>6.621080</td>\n",
       "      <td>5.022666</td>\n",
       "      <td>0.226135</td>\n",
       "      <td>6.621080</td>\n",
       "      <td>5.022666</td>\n",
       "      <td>1</td>\n",
       "      <td>True</td>\n",
       "      <td>6</td>\n",
       "    </tr>\n",
       "    <tr>\n",
       "      <th>8</th>\n",
       "      <td>ExtraTreesGini_BAG_L1</td>\n",
       "      <td>0.603587</td>\n",
       "      <td>0.607758</td>\n",
       "      <td>0.219050</td>\n",
       "      <td>6.483004</td>\n",
       "      <td>4.992307</td>\n",
       "      <td>0.219050</td>\n",
       "      <td>6.483004</td>\n",
       "      <td>4.992307</td>\n",
       "      <td>1</td>\n",
       "      <td>True</td>\n",
       "      <td>5</td>\n",
       "    </tr>\n",
       "    <tr>\n",
       "      <th>9</th>\n",
       "      <td>ExtraTreesEntr_BAG_L2</td>\n",
       "      <td>0.594278</td>\n",
       "      <td>0.797837</td>\n",
       "      <td>5.323759</td>\n",
       "      <td>48.077293</td>\n",
       "      <td>25.159343</td>\n",
       "      <td>0.204047</td>\n",
       "      <td>6.569059</td>\n",
       "      <td>3.400829</td>\n",
       "      <td>2</td>\n",
       "      <td>True</td>\n",
       "      <td>11</td>\n",
       "    </tr>\n",
       "    <tr>\n",
       "      <th>10</th>\n",
       "      <td>KNeighborsDist_BAG_L1</td>\n",
       "      <td>0.586945</td>\n",
       "      <td>0.573644</td>\n",
       "      <td>2.094145</td>\n",
       "      <td>7.176513</td>\n",
       "      <td>0.287064</td>\n",
       "      <td>2.094145</td>\n",
       "      <td>7.176513</td>\n",
       "      <td>0.287064</td>\n",
       "      <td>1</td>\n",
       "      <td>True</td>\n",
       "      <td>2</td>\n",
       "    </tr>\n",
       "    <tr>\n",
       "      <th>11</th>\n",
       "      <td>KNeighborsUnif_BAG_L1</td>\n",
       "      <td>0.575366</td>\n",
       "      <td>0.569454</td>\n",
       "      <td>2.130051</td>\n",
       "      <td>7.145497</td>\n",
       "      <td>0.290066</td>\n",
       "      <td>2.130051</td>\n",
       "      <td>7.145497</td>\n",
       "      <td>0.290066</td>\n",
       "      <td>1</td>\n",
       "      <td>True</td>\n",
       "      <td>1</td>\n",
       "    </tr>\n",
       "  </tbody>\n",
       "</table>\n",
       "</div>"
      ],
      "text/plain": [
       "                      model  score_test  score_val  pred_time_test  \\\n",
       "0   RandomForestEntr_BAG_L2    0.614975   0.801908        5.300791   \n",
       "1   RandomForestGini_BAG_L1    0.613703   0.609850        0.221553   \n",
       "2   RandomForestGini_BAG_L2    0.611673   0.798771        5.316757   \n",
       "3   RandomForestEntr_BAG_L1    0.609681   0.610286        0.228779   \n",
       "4     ExtraTreesGini_BAG_L2    0.608957   0.796278        5.321757   \n",
       "5       WeightedEnsemble_L2    0.608403   0.613442        0.903519   \n",
       "6       WeightedEnsemble_L3    0.607067   0.801874        5.707884   \n",
       "7     ExtraTreesEntr_BAG_L1    0.604699   0.609835        0.226135   \n",
       "8     ExtraTreesGini_BAG_L1    0.603587   0.607758        0.219050   \n",
       "9     ExtraTreesEntr_BAG_L2    0.594278   0.797837        5.323759   \n",
       "10    KNeighborsDist_BAG_L1    0.586945   0.573644        2.094145   \n",
       "11    KNeighborsUnif_BAG_L1    0.575366   0.569454        2.130051   \n",
       "\n",
       "    pred_time_val   fit_time  pred_time_test_marginal  pred_time_val_marginal  \\\n",
       "0       47.884419  24.368791                 0.181079                6.376185   \n",
       "1        6.929353   5.654842                 0.221553                6.929353   \n",
       "2       47.908111  24.642530                 0.197045                6.399877   \n",
       "3        7.152787   5.511570                 0.228779                7.152787   \n",
       "4       47.958304  25.241310                 0.202045                6.450070   \n",
       "5       27.195234  26.262874                 0.008002                0.009010   \n",
       "6       60.868359  35.603527                 0.006001                0.015005   \n",
       "7        6.621080   5.022666                 0.226135                6.621080   \n",
       "8        6.483004   4.992307                 0.219050                6.483004   \n",
       "9       48.077293  25.159343                 0.204047                6.569059   \n",
       "10       7.176513   0.287064                 2.094145                7.176513   \n",
       "11       7.145497   0.290066                 2.130051                7.145497   \n",
       "\n",
       "    fit_time_marginal  stack_level  can_infer  fit_order  \n",
       "0            2.610276            2       True          9  \n",
       "1            5.654842            1       True          3  \n",
       "2            2.884016            2       True          8  \n",
       "3            5.511570            1       True          4  \n",
       "4            3.482795            2       True         10  \n",
       "5            5.081489            2       True          7  \n",
       "6            4.949892            3       True         12  \n",
       "7            5.022666            1       True          6  \n",
       "8            4.992307            1       True          5  \n",
       "9            3.400829            2       True         11  \n",
       "10           0.287064            1       True          2  \n",
       "11           0.290066            1       True          1  "
      ]
     },
     "execution_count": 9,
     "metadata": {},
     "output_type": "execute_result"
    }
   ],
   "source": [
    "test_data = TabularDataset('C:\\\\Users\\\\whchi\\\\Downloads\\\\Log-diagnosis-main\\\\Log-diagnosis-main\\\\pre_contest\\\\dataset\\\\test.csv')\n",
    "predictor.leaderboard(test_data, silent=True)"
   ]
  },
  {
   "cell_type": "code",
   "execution_count": 10,
   "id": "e6c57698",
   "metadata": {},
   "outputs": [
    {
     "name": "stderr",
     "output_type": "stream",
     "text": [
      "Loaded data from: C:\\Users\\whchi\\Downloads\\Log-diagnosis-main\\Log-diagnosis-main\\pre_contest\\dataset\\data_copy.csv | Columns = 2 / 2 | Rows = 16604 -> 16604\n",
      "No path specified. Models will be saved in: \"AutogluonModels/ag-20220326_115844\\\"\n",
      "Beginning AutoGluon training ... Time limit = 60s\n",
      "AutoGluon will save models to \"AutogluonModels/ag-20220326_115844\\\"\n",
      "AutoGluon Version:  0.4.0\n",
      "Python Version:     3.9.0\n",
      "Operating System:   Windows\n",
      "Train Data Rows:    16604\n",
      "Train Data Columns: 1\n",
      "Label Column: label\n",
      "Preprocessing data ...\n",
      "AutoGluon infers your prediction problem is: 'multiclass' (because dtype of label-column == int, but few unique label-values observed).\n",
      "\t4 unique label values:  [1, 2, 3, 0]\n",
      "\tIf 'multiclass' is not the correct problem_type, please manually specify the problem_type parameter during predictor init (You may specify problem_type as one of: ['binary', 'multiclass', 'regression'])\n",
      "Train Data Class Count: 4\n",
      "Using Feature Generators to preprocess the data ...\n",
      "Fitting AutoMLPipelineFeatureGenerator...\n",
      "\tAvailable Memory:                    17079.32 MB\n",
      "\tTrain Data (Original)  Memory Usage: 4.6 MB (0.0% of available memory)\n",
      "\tInferring data type of each feature based on column values. Set feature_metadata_in to manually specify special dtypes of the features.\n",
      "\tStage 1 Generators:\n",
      "\t\tFitting AsTypeFeatureGenerator...\n",
      "\tStage 2 Generators:\n",
      "\t\tFitting FillNaFeatureGenerator...\n",
      "\tStage 3 Generators:\n",
      "\t\tFitting CategoryFeatureGenerator...\n",
      "\t\t\tFitting CategoryMemoryMinimizeFeatureGenerator...\n",
      "\t\tFitting TextSpecialFeatureGenerator...\n",
      "\t\t\tFitting BinnedFeatureGenerator...\n",
      "\t\t\tFitting DropDuplicatesFeatureGenerator...\n",
      "\t\tFitting TextNgramFeatureGenerator...\n",
      "\t\t\tFitting CountVectorizer for text features: ['msg']\n",
      "\t\t\tCountVectorizer fit with vocabulary size = 1766\n",
      "\tStage 4 Generators:\n",
      "\t\tFitting DropUniqueFeatureGenerator...\n",
      "\tTypes of features in original data (raw dtype, special dtypes):\n",
      "\t\t('object', ['text']) : 1 | ['msg']\n",
      "\tTypes of features in processed data (raw dtype, special dtypes):\n",
      "\t\t('category', ['text_as_category'])  :    1 | ['msg']\n",
      "\t\t('int', ['binned', 'text_special']) :   18 | ['msg.char_count', 'msg.word_count', 'msg.capital_ratio', 'msg.lower_ratio', 'msg.digit_ratio', ...]\n",
      "\t\t('int', ['text_ngram'])             : 1767 | ['__nlp__.000000', '__nlp__.000000 0203c0a80101', '__nlp__.000000 0203c0a80101 processor', '__nlp__.001c4c', '__nlp__.0203c0a80101', ...]\n",
      "\t6.2s = Fit runtime\n",
      "\t1 features in original data used to generate 1786 features in processed data.\n",
      "\tTrain Data (Processed) Memory Usage: 59.01 MB (0.3% of available memory)\n",
      "Data preprocessing and feature engineering runtime = 6.33s ...\n",
      "AutoGluon will gauge predictive performance using evaluation metric: 'macro_f1'\n",
      "\tTo change this, specify the eval_metric parameter of Predictor()\n",
      "Automatically generating train/validation split with holdout_frac=0.1, Train Rows: 14943, Val Rows: 1661\n",
      "Fitting 13 L1 models ...\n",
      "Fitting model: KNeighborsUnif ... Training model for up to 53.67s of the 53.66s of remaining time.\n",
      "\t0.5691\t = Validation score   (macro_f1)\n",
      "\t0.52s\t = Training   runtime\n",
      "\t1.29s\t = Validation runtime\n",
      "Fitting model: KNeighborsDist ... Training model for up to 51.75s of the 51.73s of remaining time.\n",
      "\t0.5771\t = Validation score   (macro_f1)\n",
      "\t0.54s\t = Training   runtime\n",
      "\t1.26s\t = Validation runtime\n",
      "Fitting model: NeuralNetFastAI ... Training model for up to 49.84s of the 49.82s of remaining time.\n",
      "Metric macro_f1 is not supported by this model - using log_loss instead\n",
      "\t0.5134\t = Validation score   (macro_f1)\n",
      "\t15.14s\t = Training   runtime\n",
      "\t0.02s\t = Validation runtime\n",
      "Fitting model: LightGBMXT ... Training model for up to 34.63s of the 34.61s of remaining time.\n",
      "\t0.6052\t = Validation score   (macro_f1)\n",
      "\t19.54s\t = Training   runtime\n",
      "\t0.05s\t = Validation runtime\n",
      "Fitting model: LightGBM ... Training model for up to 14.98s of the 14.94s of remaining time.\n",
      "\tRan out of time, early stopping on iteration 234. Best iteration is:\n",
      "\t[57]\tvalid_set's multi_logloss: 0.402318\tvalid_set's macro_f1: 0.589821\n",
      "\t0.5898\t = Validation score   (macro_f1)\n",
      "\t15.38s\t = Training   runtime\n",
      "\t0.05s\t = Validation runtime\n",
      "Fitting model: WeightedEnsemble_L2 ... Training model for up to 53.67s of the -3.68s of remaining time.\n",
      "\t0.6063\t = Validation score   (macro_f1)\n",
      "\t1.12s\t = Training   runtime\n",
      "\t0.0s\t = Validation runtime\n",
      "AutoGluon training complete, total runtime = 65.01s ... Best model: \"WeightedEnsemble_L2\"\n",
      "TabularPredictor saved. To load, use: predictor = TabularPredictor.load(\"AutogluonModels/ag-20220326_115844\\\")\n"
     ]
    }
   ],
   "source": [
    "data = TabularDataset('C:\\\\Users\\\\whchi\\\\Downloads\\\\Log-diagnosis-main\\\\Log-diagnosis-main\\\\pre_contest\\\\dataset\\\\data_copy.csv')\n",
    "time_limit = 60\n",
    "predictor2 = TabularPredictor(label='label',eval_metric=ag_macro_f1_scorer).fit(train_data=data,time_limit=time_limit)"
   ]
  }
 ],
 "metadata": {
  "kernelspec": {
   "display_name": "Log_diagnosis",
   "language": "python",
   "name": "log_diagnosis"
  },
  "language_info": {
   "codemirror_mode": {
    "name": "ipython",
    "version": 3
   },
   "file_extension": ".py",
   "mimetype": "text/x-python",
   "name": "python",
   "nbconvert_exporter": "python",
   "pygments_lexer": "ipython3",
   "version": "3.8.12"
  }
 },
 "nbformat": 4,
 "nbformat_minor": 5
}
